CRITICAL:root:
Date:2021-05-05 11:32:24.349511
Traceback (most recent call last):
  File "nodcast.py", line 5867, in <module>
    main()
  File "nodcast.py", line 5859, in main
    wrapper(start)
  File "/home/ahmad/miniconda3/lib/python3.8/curses/__init__.py", line 105, in wrapper
    return func(stdscr, *args, **kwds)
  File "nodcast.py", line 4856, in start
    list_articles(last_visited, "Recent Articles", group="last_visited")
  File "nodcast.py", line 1095, in list_articles
    show_article(articles[k])
  File "nodcast.py", line 2586, in show_article
    show_info(art["title"] + "\n" + art["tags"] + "\n" + art["localPdfUrl"],
TypeError: can only concatenate str (not "list") to str
CRITICAL:root:
Date:2021-05-06 14:29:27.189036
Traceback (most recent call last):
  File "nodcast.py", line 5867, in <module>
    main()
  File "nodcast.py", line 5859, in main
    wrapper(start)
  File "/home/ahmad/miniconda3/lib/python3.8/curses/__init__.py", line 105, in wrapper
    return func(stdscr, *args, **kwds)
  File "nodcast.py", line 4867, in start
    show_files(save_folder, exts=['*.txt', '*.artid', "*.listid", '*.art','*.pdf','*.list','*.json','*.squad','*.prc'], extract=True)
  File "nodcast.py", line 5077, in show_files
    show_files(save_pdf_folder, exts, depth + 1)
  File "nodcast.py", line 5134, in show_files
    show_article(art)
  File "nodcast.py", line 2586, in show_article
    show_info(art["title"] + "\nTags: " + " ,".join(art["tags"]),
KeyError: 'tags'
CRITICAL:root:
Date:2021-05-08 12:14:31.477947
Traceback (most recent call last):
  File "nodcast.py", line 5867, in <module>
    main()
  File "nodcast.py", line 5859, in main
    wrapper(start)
  File "/home/ahmad/miniconda3/lib/python3.8/curses/__init__.py", line 105, in wrapper
    return func(stdscr, *args, **kwds)
  File "nodcast.py", line 4867, in start
    show_files(save_folder, exts=['*.txt', '*.artid', "*.listid", '*.art','*.pdf','*.list','*.json','*.squad','*.prc'], extract=True)
  File "nodcast.py", line 5077, in show_files
    show_files(save_pdf_folder, exts, depth + 1)
  File "nodcast.py", line 5113, in show_files
    show_article(art)
  File "nodcast.py", line 3209, in show_article
    text_content = extractText(pdf_fname)
NameError: name 'pdf_fname' is not defined
CRITICAL:root:
Date:2021-05-10 15:44:44.438825
Traceback (most recent call last):
  File "nodcast.py", line 5868, in <module>
    main()
  File "nodcast.py", line 5860, in main
    wrapper(start)
  File "/home/ahmad/miniconda3/lib/python3.8/curses/__init__.py", line 105, in wrapper
    return func(stdscr, *args, **kwds)
  File "nodcast.py", line 4857, in start
    list_articles(last_visited, "Recent Articles", group="last_visited")
  File "nodcast.py", line 1095, in list_articles
    show_article(articles[k])
  File "nodcast.py", line 2690, in show_article
    _c = unset_sent(sents[si])
  File "nodcast.py", line 1664, in unset_sent
    last_note = list(sent["notes"])[-1]
IndexError: list index out of range
CRITICAL:root:
Date:2021-05-10 15:48:13.484884
Traceback (most recent call last):
  File "nodcast.py", line 5869, in <module>
    main()
  File "nodcast.py", line 5861, in main
    wrapper(start)
  File "/home/ahmad/miniconda3/lib/python3.8/curses/__init__.py", line 105, in wrapper
    return func(stdscr, *args, **kwds)
  File "nodcast.py", line 4858, in start
    list_articles(last_visited, "Recent Articles", group="last_visited")
  File "nodcast.py", line 1095, in list_articles
    show_article(articles[k])
  File "nodcast.py", line 2577, in show_article
    show_info(art["title"], delay=3000)
TypeError: show_info() got an unexpected keyword argument 'delay'
CRITICAL:root:
Date:2021-05-11 07:52:45.129473
Traceback (most recent call last):
  File "nodcast.py", line 5872, in <module>
    main()
  File "nodcast.py", line 5864, in main
    wrapper(start)
  File "/home/ahmad/miniconda3/lib/python3.8/curses/__init__.py", line 105, in wrapper
    return func(stdscr, *args, **kwds)
  File "nodcast.py", line 4861, in start
    list_articles(last_visited, "Recent Articles", group="last_visited")
  File "nodcast.py", line 1095, in list_articles
    show_article(articles[k])
  File "nodcast.py", line 2562, in show_article
    if view_title:
UnboundLocalError: local variable 'view_title' referenced before assignment
CRITICAL:root:
Date:2021-05-14 09:29:37.897732
Traceback (most recent call last):
  File "nodcast.py", line 5875, in <module>
    main()
  File "nodcast.py", line 5867, in main
    wrapper(start)
  File "/home/ahmad/miniconda3/lib/python3.8/curses/__init__.py", line 105, in wrapper
    return func(stdscr, *args, **kwds)
  File "nodcast.py", line 4864, in start
    list_articles(last_visited, "Recent Articles", group="last_visited")
  File "nodcast.py", line 1095, in list_articles
    show_article(articles[k])
  File "nodcast.py", line 2053, in show_article
    cur_pos = hl_pos if hl_pos > 0 else pos[cur_mark]
TypeError: '>' not supported between instances of 'tuple' and 'int'
CRITICAL:root:
Date:2021-05-15 12:15:29.648344
Traceback (most recent call last):
  File "nodcast.py", line 5898, in <module>
    main()
  File "nodcast.py", line 5890, in main
    wrapper(start)
  File "/home/ahmad/miniconda3/lib/python3.8/curses/__init__.py", line 105, in wrapper
    return func(stdscr, *args, **kwds)
  File "nodcast.py", line 4873, in start
    show_files(save_folder, exts=['*.txt', '*.artid', "*.listid", '*.art','*.pdf','*.list','*.json','*.squad','*.prc'], extract=True)
  File "nodcast.py", line 5046, in show_files
    text = extractText(psf_fname)
NameError: name 'psf_fname' is not defined
CRITICAL:root:
Date:2021-05-15 12:16:02.182600
Traceback (most recent call last):
  File "nodcast.py", line 5898, in <module>
    main()
  File "nodcast.py", line 5890, in main
    wrapper(start)
  File "/home/ahmad/miniconda3/lib/python3.8/curses/__init__.py", line 105, in wrapper
    return func(stdscr, *args, **kwds)
  File "nodcast.py", line 4873, in start
    show_files(save_folder, exts=['*.txt', '*.artid', "*.listid", '*.art','*.pdf','*.list','*.json','*.squad','*.prc'], extract=True)
  File "nodcast.py", line 5054, in show_files
    text = pdf_file + "\n" + pages + "\n" + text
UnboundLocalError: local variable 'pages' referenced before assignment
CRITICAL:root:
Date:2021-05-15 12:39:25.436530
Traceback (most recent call last):
  File "nodcast.py", line 5898, in <module>
    main()
  File "nodcast.py", line 5890, in main
    wrapper(start)
  File "/home/ahmad/miniconda3/lib/python3.8/curses/__init__.py", line 105, in wrapper
    return func(stdscr, *args, **kwds)
  File "nodcast.py", line 4873, in start
    show_files(save_folder, exts=['*.txt', '*.artid', "*.listid", '*.art','*.pdf','*.list','*.json','*.squad','*.prc'], extract=True)
  File "nodcast.py", line 4981, in show_files
    show_files(sfolder, exts, depth + 1)
  File "nodcast.py", line 4985, in show_files
    list_tags(save_folder)
  File "nodcast.py", line 5576, in list_tags
    ti, _ = select_box({"Tags":opts}, tag_win, 0, in_row=False, border=True, ret_index =True)
  File "nodcast.py", line 4127, in select_box
    _size = max([len(s) for s in opts]) + 2
ValueError: max() arg is an empty sequence
CRITICAL:root:
Date:2021-05-16 14:29:08.158813
Traceback (most recent call last):
  File "nodcast.py", line 5899, in <module>
    main()
  File "nodcast.py", line 5891, in main
    wrapper(start)
  File "/home/ahmad/miniconda3/lib/python3.8/curses/__init__.py", line 105, in wrapper
    return func(stdscr, *args, **kwds)
  File "nodcast.py", line 4873, in start
    show_files(save_folder, exts=['*.txt', '*.artid', "*.listid", '*.art','*.pdf','*.list','*.json','*.squad','*.prc'], extract=True)
  File "nodcast.py", line 5134, in show_files
    elif not ref_artid in art["refs"]:
UnboundLocalError: local variable 'ref_artid' referenced before assignment
CRITICAL:root:
Date:2021-05-16 14:32:32.123590
Traceback (most recent call last):
  File "nodcast.py", line 5899, in <module>
    main()
  File "nodcast.py", line 5891, in main
    wrapper(start)
  File "/home/ahmad/miniconda3/lib/python3.8/curses/__init__.py", line 105, in wrapper
    return func(stdscr, *args, **kwds)
  File "nodcast.py", line 4873, in start
    show_files(save_folder, exts=['*.txt', '*.artid', "*.listid", '*.art','*.pdf','*.list','*.json','*.squad','*.prc'], extract=True)
  File "nodcast.py", line 5176, in show_files
    list_artids(artids, fid=name, group=group)
  File "nodcast.py", line 944, in list_artids
    arts = list_articles(articles, fid, group=group)
  File "nodcast.py", line 1013, in list_articles
    review = a["sections"][0]["fragments"][0]["sents"][0]
IndexError: list index out of range
CRITICAL:root:
Date:2021-05-16 14:35:07.414946
Traceback (most recent call last):
  File "nodcast.py", line 5899, in <module>
    main()
  File "nodcast.py", line 5891, in main
    wrapper(start)
  File "/home/ahmad/miniconda3/lib/python3.8/curses/__init__.py", line 105, in wrapper
    return func(stdscr, *args, **kwds)
  File "nodcast.py", line 4873, in start
    show_files(save_folder, exts=['*.txt', '*.artid', "*.listid", '*.art','*.pdf','*.list','*.json','*.squad','*.prc'], extract=True)
  File "nodcast.py", line 5176, in show_files
    list_artids(artids, fid=name, group=group)
  File "nodcast.py", line 944, in list_artids
    arts = list_articles(articles, fid, group=group)
  File "nodcast.py", line 1013, in list_articles
    review = a["sections"][0]["fragments"][0]["sents"][0]
IndexError: list index out of range
CRITICAL:root:
Date:2021-05-16 14:52:26.313770
Traceback (most recent call last):
  File "nodcast.py", line 5900, in <module>
    main()
  File "nodcast.py", line 5892, in main
    wrapper(start)
  File "/home/ahmad/miniconda3/lib/python3.8/curses/__init__.py", line 105, in wrapper
    return func(stdscr, *args, **kwds)
  File "nodcast.py", line 4874, in start
    show_files(save_folder, exts=['*.txt', '*.artid', "*.listid", '*.art','*.pdf','*.list','*.json','*.squad','*.prc'], extract=True)
  File "nodcast.py", line 5177, in show_files
    list_artids(artids, fid=name, group=group)
  File "nodcast.py", line 944, in list_artids
    arts = list_articles(articles, fid, group=group)
  File "nodcast.py", line 1014, in list_articles
    review = a["sections"][0]["fragments"][0]["sents"][0]
IndexError: list index out of range
CRITICAL:root:
Date:2021-05-22 09:26:49.302134
Traceback (most recent call last):
  File "nodcast.py", line 5897, in <module>
    main()
  File "nodcast.py", line 5889, in main
    wrapper(start)
  File "/home/ahmad/miniconda3/lib/python3.8/curses/__init__.py", line 105, in wrapper
    return func(stdscr, *args, **kwds)
  File "nodcast.py", line 4871, in start
    show_files(save_folder, exts=['*.txt', '*.artid', "*.listid", '*.art','*.pdf','*.list','*.json','*.squad','*.prc'], extract=True)
  File "nodcast.py", line 5150, in show_files
    with open(ref_artid, 'w') as outfile:
FileNotFoundError: [Errno 2] No such file or directory: '/home/ahmad/Documents/Checkideh/Common Sense RC/Files/2021-05-22/978-1-5090-4117-6/17/$31.00 ©2017 IEEE.artid'
CRITICAL:root:
Date:2021-05-26 11:08:58.623764
Traceback (most recent call last):
  File "nodcast.py", line 5899, in <module>
    main()
  File "nodcast.py", line 5891, in main
    wrapper(start)
  File "/home/ahmad/miniconda3/lib/python3.8/curses/__init__.py", line 105, in wrapper
    return func(stdscr, *args, **kwds)
  File "nodcast.py", line 4862, in start
    list_articles(last_visited, "Recent Articles", group="last_visited")
  File "nodcast.py", line 1097, in list_articles
    show_article(articles[k])
  File "nodcast.py", line 2427, in show_article
    show_info("sr:" + str(start_row) + " bd:" + str(begin_dist) + " ed:" + str(end_dist)  + " lr:" + str(limit_row) + " si:" + str(si) +  "bmark:" + str(bmark), delay=-1)
TypeError: show_info() got an unexpected keyword argument 'delay'
CRITICAL:root:
Date:2021-05-26 20:54:00.691014
Traceback (most recent call last):
  File "nodcast.py", line 5905, in <module>
    main()
  File "nodcast.py", line 5897, in main
    wrapper(start)
  File "/home/ahmad/miniconda3/lib/python3.8/curses/__init__.py", line 105, in wrapper
    return func(stdscr, *args, **kwds)
  File "nodcast.py", line 4879, in start
    show_files(save_folder, exts=['*.txt', '*.artid', "*.listid", '*.art','*.pdf','*.list','*.json','*.squad','*.prc'], extract=True)
  File "nodcast.py", line 5091, in show_files
    text = extractText(filename)
  File "nodcast.py", line 349, in extractText
    interpreter.process_page(page)
  File "/home/ahmad/miniconda3/lib/python3.8/site-packages/pdfminer/pdfinterp.py", line 895, in process_page
    self.render_contents(page.resources, page.contents, ctm=ctm)
  File "/home/ahmad/miniconda3/lib/python3.8/site-packages/pdfminer/pdfinterp.py", line 908, in render_contents
    self.execute(list_value(streams))
  File "/home/ahmad/miniconda3/lib/python3.8/site-packages/pdfminer/pdfinterp.py", line 933, in execute
    func(*args)
  File "/home/ahmad/miniconda3/lib/python3.8/site-packages/pdfminer/pdfinterp.py", line 870, in do_Do
    self.device.begin_figure(xobjid, bbox, matrix)
  File "/home/ahmad/miniconda3/lib/python3.8/site-packages/pdfminer/converter.py", line 57, in begin_figure
    self.cur_item = LTFigure(name, bbox, mult_matrix(matrix, self.ctm))
  File "/home/ahmad/miniconda3/lib/python3.8/site-packages/pdfminer/layout.py", line 833, in __init__
    bounds = ((x, y), (x + w, y), (x, y + h), (x + w, y + h))
TypeError: unsupported operand type(s) for +: 'int' and 'PDFObjRef'
CRITICAL:root:
Date:2021-05-26 20:54:39.931265
Traceback (most recent call last):
  File "nodcast.py", line 5905, in <module>
    main()
  File "nodcast.py", line 5897, in main
    wrapper(start)
  File "/home/ahmad/miniconda3/lib/python3.8/curses/__init__.py", line 105, in wrapper
    return func(stdscr, *args, **kwds)
  File "nodcast.py", line 4879, in start
    show_files(save_folder, exts=['*.txt', '*.artid', "*.listid", '*.art','*.pdf','*.list','*.json','*.squad','*.prc'], extract=True)
  File "nodcast.py", line 5091, in show_files
    text = extractText(filename)
  File "nodcast.py", line 349, in extractText
    interpreter.process_page(page)
  File "/home/ahmad/miniconda3/lib/python3.8/site-packages/pdfminer/pdfinterp.py", line 895, in process_page
    self.render_contents(page.resources, page.contents, ctm=ctm)
  File "/home/ahmad/miniconda3/lib/python3.8/site-packages/pdfminer/pdfinterp.py", line 908, in render_contents
    self.execute(list_value(streams))
  File "/home/ahmad/miniconda3/lib/python3.8/site-packages/pdfminer/pdfinterp.py", line 933, in execute
    func(*args)
  File "/home/ahmad/miniconda3/lib/python3.8/site-packages/pdfminer/pdfinterp.py", line 870, in do_Do
    self.device.begin_figure(xobjid, bbox, matrix)
  File "/home/ahmad/miniconda3/lib/python3.8/site-packages/pdfminer/converter.py", line 57, in begin_figure
    self.cur_item = LTFigure(name, bbox, mult_matrix(matrix, self.ctm))
  File "/home/ahmad/miniconda3/lib/python3.8/site-packages/pdfminer/layout.py", line 833, in __init__
    bounds = ((x, y), (x + w, y), (x, y + h), (x + w, y + h))
TypeError: unsupported operand type(s) for +: 'int' and 'PDFObjRef'
CRITICAL:root:
Date:2021-05-27 11:21:28.949582
Traceback (most recent call last):
  File "nodcast.py", line 5909, in <module>
    main()
  File "nodcast.py", line 5901, in main
    wrapper(start)
  File "/home/ahmad/miniconda3/lib/python3.8/curses/__init__.py", line 105, in wrapper
    return func(stdscr, *args, **kwds)
  File "nodcast.py", line 4872, in start
    list_articles(last_visited, "Recent Articles", group="last_visited")
  File "nodcast.py", line 1101, in list_articles
    show_article(articles[k])
  File "nodcast.py", line 3293, in show_article
    _comment, ret_ch = minput(win, 0, 0, note_title,
  File "/home/ahmad/recs/nodcast/nodcast/util.py", line 245, in minput
    subprocess.run('sudo setxkbmap -layout ir')
NameError: name 'subprocess' is not defined
CRITICAL:root:
Date:2021-05-27 11:22:16.305494
Traceback (most recent call last):
  File "nodcast.py", line 5909, in <module>
    main()
  File "nodcast.py", line 5901, in main
    wrapper(start)
  File "/home/ahmad/miniconda3/lib/python3.8/curses/__init__.py", line 105, in wrapper
    return func(stdscr, *args, **kwds)
  File "nodcast.py", line 4872, in start
    list_articles(last_visited, "Recent Articles", group="last_visited")
  File "nodcast.py", line 1101, in list_articles
    show_article(articles[k])
  File "nodcast.py", line 3293, in show_article
    _comment, ret_ch = minput(win, 0, 0, note_title,
  File "/home/ahmad/recs/nodcast/nodcast/util.py", line 246, in minput
    subprocess.run('sudo setxkbmap -layout ir')
  File "/home/ahmad/miniconda3/lib/python3.8/subprocess.py", line 489, in run
    with Popen(*popenargs, **kwargs) as process:
  File "/home/ahmad/miniconda3/lib/python3.8/subprocess.py", line 854, in __init__
    self._execute_child(args, executable, preexec_fn, close_fds,
  File "/home/ahmad/miniconda3/lib/python3.8/subprocess.py", line 1702, in _execute_child
    raise child_exception_type(errno_num, err_msg, err_filename)
FileNotFoundError: [Errno 2] No such file or directory: 'sudo setxkbmap -layout ir'
CRITICAL:root:
Date:2021-05-27 11:24:19.839853
Traceback (most recent call last):
  File "nodcast.py", line 5909, in <module>
    main()
  File "nodcast.py", line 5901, in main
    wrapper(start)
  File "/home/ahmad/miniconda3/lib/python3.8/curses/__init__.py", line 105, in wrapper
    return func(stdscr, *args, **kwds)
  File "nodcast.py", line 4872, in start
    list_articles(last_visited, "Recent Articles", group="last_visited")
  File "nodcast.py", line 1101, in list_articles
    show_article(articles[k])
  File "nodcast.py", line 3293, in show_article
    _comment, ret_ch = minput(win, 0, 0, note_title,
  File "/home/ahmad/recs/nodcast/nodcast/util.py", line 246, in minput
    subprocess.call('setxkbmap -layout ir')
  File "/home/ahmad/miniconda3/lib/python3.8/subprocess.py", line 340, in call
    with Popen(*popenargs, **kwargs) as p:
  File "/home/ahmad/miniconda3/lib/python3.8/subprocess.py", line 854, in __init__
    self._execute_child(args, executable, preexec_fn, close_fds,
  File "/home/ahmad/miniconda3/lib/python3.8/subprocess.py", line 1702, in _execute_child
    raise child_exception_type(errno_num, err_msg, err_filename)
FileNotFoundError: [Errno 2] No such file or directory: 'setxkbmap -layout ir'
CRITICAL:root:
Date:2021-05-27 11:25:04.177770
Traceback (most recent call last):
  File "nodcast.py", line 5909, in <module>
    main()
  File "nodcast.py", line 5901, in main
    wrapper(start)
  File "/home/ahmad/miniconda3/lib/python3.8/curses/__init__.py", line 105, in wrapper
    return func(stdscr, *args, **kwds)
  File "nodcast.py", line 4872, in start
    list_articles(last_visited, "Recent Articles", group="last_visited")
  File "nodcast.py", line 1101, in list_articles
    show_article(articles[k])
  File "nodcast.py", line 3293, in show_article
    _comment, ret_ch = minput(win, 0, 0, note_title,
  File "/home/ahmad/recs/nodcast/nodcast/util.py", line 246, in minput
    subprocess.run('setxkbmap -layout ir')
  File "/home/ahmad/miniconda3/lib/python3.8/subprocess.py", line 489, in run
    with Popen(*popenargs, **kwargs) as process:
  File "/home/ahmad/miniconda3/lib/python3.8/subprocess.py", line 854, in __init__
    self._execute_child(args, executable, preexec_fn, close_fds,
  File "/home/ahmad/miniconda3/lib/python3.8/subprocess.py", line 1702, in _execute_child
    raise child_exception_type(errno_num, err_msg, err_filename)
FileNotFoundError: [Errno 2] No such file or directory: 'setxkbmap -layout ir'
CRITICAL:root:
Date:2021-05-27 17:03:28.446413
Traceback (most recent call last):
  File "nodcast.py", line 5910, in <module>
    main()
  File "nodcast.py", line 5902, in main
    wrapper(start)
  File "/home/ahmad/miniconda3/lib/python3.8/curses/__init__.py", line 105, in wrapper
    return func(stdscr, *args, **kwds)
  File "nodcast.py", line 4883, in start
    show_files(save_folder, exts=['*.txt', '*.artid', "*.listid", '*.art','*.pdf','*.list','*.json','*.squad','*.prc'], extract=True)
  File "nodcast.py", line 4992, in show_files
    menu, sk, menu_len = refresh_files(save_folder, subfolders, files, depth, show_folders)
  File "nodcast.py", line 4932, in refresh_files
    if show_folders or sf.endswith(today) or sf.endswith(yesterday) or not match.group(1):
AttributeError: 'NoneType' object has no attribute 'group'
CRITICAL:root:
Date:2021-05-27 17:05:46.433732
Traceback (most recent call last):
  File "nodcast.py", line 5909, in <module>
    main()
  File "nodcast.py", line 5901, in main
    wrapper(start)
  File "/home/ahmad/miniconda3/lib/python3.8/curses/__init__.py", line 105, in wrapper
    return func(stdscr, *args, **kwds)
  File "nodcast.py", line 4883, in start
    show_files(save_folder, exts=['*.txt', '*.artid', "*.listid", '*.art','*.pdf','*.list','*.json','*.squad','*.prc'], extract=True)
  File "nodcast.py", line 4991, in show_files
    menu, sk, menu_len = refresh_files(save_folder, subfolders, files, depth, show_folders)
  File "nodcast.py", line 4931, in refresh_files
    if show_folders or sf.endswith(today) or sf.endswith(yesterday) or not valid_date(sf):
  File "/home/ahmad/recs/nodcast/nodcast/util.py", line 243, in valid_date
    datetime.datetime.strptime(datestring, '%Y-%m-%d')
NameError: name 'datetime' is not defined
CRITICAL:root:
Date:2021-05-27 22:18:46.217952
Traceback (most recent call last):
  File "nodcast.py", line 5910, in <module>
    main()
  File "nodcast.py", line 5902, in main
    wrapper(start)
  File "/home/ahmad/miniconda3/lib/python3.8/curses/__init__.py", line 105, in wrapper
    return func(stdscr, *args, **kwds)
  File "nodcast.py", line 4883, in start
    show_files(save_folder, exts=['*.txt', '*.artid', "*.listid", '*.art','*.pdf','*.list','*.json','*.squad','*.prc'], extract=True)
  File "nodcast.py", line 4975, in show_files
    subfolders.sort(key=os.path.getctime, reverse=True)
  File "/home/ahmad/miniconda3/lib/python3.8/genericpath.py", line 65, in getctime
    return os.stat(filename).st_ctime
FileNotFoundError: [Errno 2] No such file or directory: '000-Completion'
CRITICAL:root:
Date:2021-05-27 22:20:52.221704
Traceback (most recent call last):
  File "nodcast.py", line 5910, in <module>
    main()
  File "nodcast.py", line 5902, in main
    wrapper(start)
  File "/home/ahmad/miniconda3/lib/python3.8/curses/__init__.py", line 105, in wrapper
    return func(stdscr, *args, **kwds)
  File "nodcast.py", line 4883, in start
    show_files(save_folder, exts=['*.txt', '*.artid', "*.listid", '*.art','*.pdf','*.list','*.json','*.squad','*.prc'], extract=True)
  File "nodcast.py", line 4992, in show_files
    menu, sk, menu_len = refresh_files(save_folder, subfolders, files, depth, show_folders)
  File "nodcast.py", line 4931, in refresh_files
    if show_folders or sf.endswith(today) or sf.endswith(yesterday) or not valid_date(sf):
AttributeError: 'PosixPath' object has no attribute 'endswith'
CRITICAL:root:
Date:2021-05-29 09:56:26.708595
Traceback (most recent call last):
  File "nodcast.py", line 5914, in <module>
    main()
  File "nodcast.py", line 5906, in main
    wrapper(start)
  File "/home/ahmad/miniconda3/lib/python3.8/curses/__init__.py", line 105, in wrapper
    return func(stdscr, *args, **kwds)
  File "nodcast.py", line 4799, in start
    ch, menu, mi = show_menu(menu, options, shortkeys=shortkeys, mi=mi, subwins=subwins, title=main_title,
  File "nodcast.py", line 4417, in show_menu
    ch = get_key(std)
  File "nodcast.py", line 54, in get_key
    ch, hotkey = ord(hotkey[0]), hotkey[1:]
TypeError: 'NoneType' object is not subscriptable
CRITICAL:root:
Date:2021-05-30 10:33:21.506029
Traceback (most recent call last):
  File "nodcast.py", line 5916, in <module>
    main()
  File "nodcast.py", line 5908, in main
    wrapper(start)
  File "/home/ahmad/miniconda3/lib/python3.8/curses/__init__.py", line 105, in wrapper
    return func(stdscr, *args, **kwds)
  File "nodcast.py", line 4891, in start
    show_files(save_folder, exts=['*.txt', '*.artid', "*.listid", '*.art','*.pdf','*.list','*.json','*.squad','*.prc'], extract=True)
  File "nodcast.py", line 5005, in show_files
    show_files(sfolder, exts, depth + 1)
  File "nodcast.py", line 5207, in show_files
    show_article(art)
  File "nodcast.py", line 3178, in show_article
    save_obj(theme_menu, theme_menu["preset"], data_dir=False, title="theme")
TypeError: save_obj() got an unexpected keyword argument 'title'
CRITICAL:root:
Date:2021-05-30 17:45:48.698358
Traceback (most recent call last):
  File "nodcast.py", line 5916, in <module>
    main()
  File "nodcast.py", line 5908, in main
    wrapper(start)
  File "/home/ahmad/miniconda3/lib/python3.8/curses/__init__.py", line 105, in wrapper
    return func(stdscr, *args, **kwds)
  File "nodcast.py", line 4891, in start
    show_files(save_folder, exts=['*.txt', '*.artid', "*.listid", '*.art','*.pdf','*.list','*.json','*.squad','*.prc'], extract=True)
  File "nodcast.py", line 5005, in show_files
    show_files(sfolder, exts, depth + 1)
  File "nodcast.py", line 5177, in show_files
    show_article(art)
  File "nodcast.py", line 3196, in show_article
    new_tit, _ch = minput(win_input, 0, 0, prompt, default= cur_sent["text"],mode = MULTI_LINE)
  File "/home/ahmad/recs/nodcast/nodcast/util.py", line 263, in minput
    print_there(mrows-1, col, footer, mwin)
  File "/home/ahmad/recs/nodcast/nodcast/util.py", line 210, in print_there
    win.addstr(x, y, text[:_len].encode(code), c)
_curses.error: addstr() returned ERR
CRITICAL:root:
Date:2021-06-05 15:31:42.129740
Traceback (most recent call last):
  File "nodcast.py", line 5916, in <module>
    main()
  File "nodcast.py", line 5908, in main
    wrapper(start)
  File "/home/ahmad/miniconda3/lib/python3.8/curses/__init__.py", line 105, in wrapper
    return func(stdscr, *args, **kwds)
  File "nodcast.py", line 4801, in start
    ch, menu, mi = show_menu(menu, options, shortkeys=shortkeys, mi=mi, subwins=subwins, title=main_title,
  File "nodcast.py", line 4355, in show_menu
    if mi + row >= _page * rows - start_rowi - 1:
NameError: name 'start_rowi' is not defined
CRITICAL:root:
Date:2021-06-07 18:14:51.583571
Traceback (most recent call last):
  File "nodcast.py", line 5928, in <module>
    main()
  File "nodcast.py", line 5920, in main
    wrapper(start)
  File "/home/ahmad/miniconda3/lib/python3.8/curses/__init__.py", line 105, in wrapper
    return func(stdscr, *args, **kwds)
  File "nodcast.py", line 4903, in start
    show_files(save_folder, exts=['*.txt', '*.artid', "*.listid", '*.art','*.pdf','*.list','*.json','*.squad','*.prc'], extract=True)
  File "nodcast.py", line 5017, in show_files
    show_files(sfolder, exts, depth + 1)
  File "nodcast.py", line 5219, in show_files
    show_article(art)
  File "nodcast.py", line 2604, in show_article
    speak(cur_sent["text"])
  File "nodcast.py", line 1725, in speak
    tts = gTTS(text=text, lang="en")
NameError: name 'gTTS' is not defined
CRITICAL:root:
Date:2021-06-07 18:48:56.538788
Traceback (most recent call last):
  File "nodcast.py", line 5941, in <module>
    main()
  File "nodcast.py", line 5933, in main
    wrapper(start)
  File "/home/ahmad/miniconda3/lib/python3.8/curses/__init__.py", line 105, in wrapper
    return func(stdscr, *args, **kwds)
  File "nodcast.py", line 4916, in start
    show_files(save_folder, exts=['*.txt', '*.artid', "*.listid", '*.art','*.pdf','*.list','*.json','*.squad','*.prc'], extract=True)
  File "nodcast.py", line 5030, in show_files
    show_files(sfolder, exts, depth + 1)
  File "nodcast.py", line 5232, in show_files
    show_article(art)
  File "nodcast.py", line 2616, in show_article
    record(sent["text"], art["title"], "sent" + ii)
TypeError: can only concatenate str (not "int") to str
CRITICAL:root:
Date:2021-06-07 18:49:32.665312
Traceback (most recent call last):
  File "nodcast.py", line 5941, in <module>
    main()
  File "nodcast.py", line 5933, in main
    wrapper(start)
  File "/home/ahmad/miniconda3/lib/python3.8/curses/__init__.py", line 105, in wrapper
    return func(stdscr, *args, **kwds)
  File "nodcast.py", line 4916, in start
    show_files(save_folder, exts=['*.txt', '*.artid', "*.listid", '*.art','*.pdf','*.list','*.json','*.squad','*.prc'], extract=True)
  File "nodcast.py", line 5030, in show_files
    show_files(sfolder, exts, depth + 1)
  File "nodcast.py", line 5232, in show_files
    show_article(art)
  File "nodcast.py", line 2616, in show_article
    record(sent["text"], art["title"], "sent_" + str(ii) )
  File "nodcast.py", line 1727, in record
    p = PosixPath('~/rec_files/'+ sound_folder)
NameError: name 'PosixPath' is not defined
CRITICAL:root:
Date:2021-06-07 18:53:18.727894
Traceback (most recent call last):
  File "nodcast.py", line 5942, in <module>
    main()
  File "nodcast.py", line 5934, in main
    wrapper(start)
  File "/home/ahmad/miniconda3/lib/python3.8/curses/__init__.py", line 105, in wrapper
    return func(stdscr, *args, **kwds)
  File "nodcast.py", line 4917, in start
    show_files(save_folder, exts=['*.txt', '*.artid', "*.listid", '*.art','*.pdf','*.list','*.json','*.squad','*.prc'], extract=True)
  File "nodcast.py", line 5031, in show_files
    show_files(sfolder, exts, depth + 1)
  File "nodcast.py", line 5233, in show_files
    show_article(art)
  File "nodcast.py", line 2617, in show_article
    record(sent["text"], art["title"], "sent_" + str(ii) )
  File "nodcast.py", line 1730, in record
    tts.save(str(p) + "/" + fil_index)
NameError: name 'fil_index' is not defined
CRITICAL:root:
Date:2021-06-07 18:54:46.377949
Traceback (most recent call last):
  File "nodcast.py", line 2617, in show_article
    record(sent["text"], art["title"], "sent_" + str(ii) )
  File "nodcast.py", line 1730, in record
    tts.save(str(p) + "/" + file_index)
  File "/home/ahmad/miniconda3/lib/python3.8/site-packages/gtts/tts.py", line 312, in save
    self.write_to_fp(f)
  File "/home/ahmad/miniconda3/lib/python3.8/site-packages/gtts/tts.py", line 263, in write_to_fp
    r = s.send(request=pr,
  File "/home/ahmad/miniconda3/lib/python3.8/site-packages/requests/sessions.py", line 643, in send
    r = adapter.send(request, **kwargs)
  File "/home/ahmad/miniconda3/lib/python3.8/site-packages/requests/adapters.py", line 439, in send
    resp = conn.urlopen(
  File "/home/ahmad/miniconda3/lib/python3.8/site-packages/urllib3/connectionpool.py", line 670, in urlopen
    httplib_response = self._make_request(
  File "/home/ahmad/miniconda3/lib/python3.8/site-packages/urllib3/connectionpool.py", line 426, in _make_request
    six.raise_from(e, None)
  File "<string>", line 3, in raise_from
  File "/home/ahmad/miniconda3/lib/python3.8/site-packages/urllib3/connectionpool.py", line 421, in _make_request
    httplib_response = conn.getresponse()
  File "/home/ahmad/miniconda3/lib/python3.8/http/client.py", line 1347, in getresponse
    response.begin()
  File "/home/ahmad/miniconda3/lib/python3.8/http/client.py", line 307, in begin
    version, status, reason = self._read_status()
  File "/home/ahmad/miniconda3/lib/python3.8/http/client.py", line 268, in _read_status
    line = str(self.fp.readline(_MAXLINE + 1), "iso-8859-1")
  File "/home/ahmad/miniconda3/lib/python3.8/socket.py", line 669, in readinto
    return self._sock.recv_into(b)
  File "/home/ahmad/miniconda3/lib/python3.8/ssl.py", line 1241, in recv_into
    return self.read(nbytes, buffer)
  File "/home/ahmad/miniconda3/lib/python3.8/ssl.py", line 1099, in read
    return self._sslobj.read(len, buffer)
KeyboardInterrupt

During handling of the above exception, another exception occurred:

Traceback (most recent call last):
  File "nodcast.py", line 5942, in <module>
    main()
  File "nodcast.py", line 5934, in main
    wrapper(start)
  File "/home/ahmad/miniconda3/lib/python3.8/curses/__init__.py", line 105, in wrapper
    return func(stdscr, *args, **kwds)
  File "nodcast.py", line 4917, in start
    show_files(save_folder, exts=['*.txt', '*.artid', "*.listid", '*.art','*.pdf','*.list','*.json','*.squad','*.prc'], extract=True)
  File "nodcast.py", line 5031, in show_files
    show_files(sfolder, exts, depth + 1)
  File "nodcast.py", line 5233, in show_files
    show_article(art)
  File "nodcast.py", line 2622, in show_article
    show_msg("Recording was canceled at" + str(rec+i), " his s again to resume")
NameError: name 'rec' is not defined
CRITICAL:root:
Date:2021-06-07 19:16:07.328956
Traceback (most recent call last):
  File "nodcast.py", line 2619, in show_article
    record(sent["text"], art["title"], "sent_" + str(ii) )
  File "nodcast.py", line 1732, in record
    tts.save(sound_file)
  File "/home/ahmad/miniconda3/lib/python3.8/site-packages/gtts/tts.py", line 312, in save
    self.write_to_fp(f)
  File "/home/ahmad/miniconda3/lib/python3.8/site-packages/gtts/tts.py", line 263, in write_to_fp
    r = s.send(request=pr,
  File "/home/ahmad/miniconda3/lib/python3.8/site-packages/requests/sessions.py", line 643, in send
    r = adapter.send(request, **kwargs)
  File "/home/ahmad/miniconda3/lib/python3.8/site-packages/requests/adapters.py", line 439, in send
    resp = conn.urlopen(
  File "/home/ahmad/miniconda3/lib/python3.8/site-packages/urllib3/connectionpool.py", line 670, in urlopen
    httplib_response = self._make_request(
  File "/home/ahmad/miniconda3/lib/python3.8/site-packages/urllib3/connectionpool.py", line 381, in _make_request
    self._validate_conn(conn)
  File "/home/ahmad/miniconda3/lib/python3.8/site-packages/urllib3/connectionpool.py", line 978, in _validate_conn
    conn.connect()
  File "/home/ahmad/miniconda3/lib/python3.8/site-packages/urllib3/connection.py", line 362, in connect
    self.sock = ssl_wrap_socket(
  File "/home/ahmad/miniconda3/lib/python3.8/site-packages/urllib3/util/ssl_.py", line 384, in ssl_wrap_socket
    return context.wrap_socket(sock, server_hostname=server_hostname)
  File "/home/ahmad/miniconda3/lib/python3.8/ssl.py", line 500, in wrap_socket
    return self.sslsocket_class._create(
  File "/home/ahmad/miniconda3/lib/python3.8/ssl.py", line 1040, in _create
    self.do_handshake()
  File "/home/ahmad/miniconda3/lib/python3.8/ssl.py", line 1309, in do_handshake
    self._sslobj.do_handshake()
KeyboardInterrupt

During handling of the above exception, another exception occurred:

Traceback (most recent call last):
  File "nodcast.py", line 5944, in <module>
    main()
  File "nodcast.py", line 5936, in main
    wrapper(start)
  File "/home/ahmad/miniconda3/lib/python3.8/curses/__init__.py", line 105, in wrapper
    return func(stdscr, *args, **kwds)
  File "nodcast.py", line 4919, in start
    show_files(save_folder, exts=['*.txt', '*.artid', "*.listid", '*.art','*.pdf','*.list','*.json','*.squad','*.prc'], extract=True)
  File "nodcast.py", line 5033, in show_files
    show_files(sfolder, exts, depth + 1)
  File "nodcast.py", line 5235, in show_files
    show_article(art)
  File "nodcast.py", line 2624, in show_article
    show_msg("Recording was canceled at" + str(rec_i), " his s again to resume")
  File "nodcast.py", line 4030, in show_msg
    show_info(msg, color)
  File "nodcast.py", line 3968, in show_info
    win_info.bkgd(' ', cur.color_pair(color))  # | cur.A_REVERSE)
TypeError: an integer is required (got type str)
CRITICAL:root:
Date:2021-06-07 19:18:05.371049
Traceback (most recent call last):
  File "nodcast.py", line 2619, in show_article
    record(sent["text"], art["title"], "sent_" + str(ii) )
  File "nodcast.py", line 1732, in record
    tts.save(sound_file)
  File "/home/ahmad/miniconda3/lib/python3.8/site-packages/gtts/tts.py", line 312, in save
    self.write_to_fp(f)
  File "/home/ahmad/miniconda3/lib/python3.8/site-packages/gtts/tts.py", line 263, in write_to_fp
    r = s.send(request=pr,
  File "/home/ahmad/miniconda3/lib/python3.8/site-packages/requests/sessions.py", line 643, in send
    r = adapter.send(request, **kwargs)
  File "/home/ahmad/miniconda3/lib/python3.8/site-packages/requests/adapters.py", line 439, in send
    resp = conn.urlopen(
  File "/home/ahmad/miniconda3/lib/python3.8/site-packages/urllib3/connectionpool.py", line 670, in urlopen
    httplib_response = self._make_request(
  File "/home/ahmad/miniconda3/lib/python3.8/site-packages/urllib3/connectionpool.py", line 381, in _make_request
    self._validate_conn(conn)
  File "/home/ahmad/miniconda3/lib/python3.8/site-packages/urllib3/connectionpool.py", line 978, in _validate_conn
    conn.connect()
  File "/home/ahmad/miniconda3/lib/python3.8/site-packages/urllib3/connection.py", line 309, in connect
    conn = self._new_conn()
  File "/home/ahmad/miniconda3/lib/python3.8/site-packages/urllib3/connection.py", line 159, in _new_conn
    conn = connection.create_connection(
  File "/home/ahmad/miniconda3/lib/python3.8/site-packages/urllib3/util/connection.py", line 61, in create_connection
    for res in socket.getaddrinfo(host, port, family, socket.SOCK_STREAM):
  File "/home/ahmad/miniconda3/lib/python3.8/socket.py", line 918, in getaddrinfo
    for res in _socket.getaddrinfo(host, port, family, type, proto, flags):
KeyboardInterrupt

During handling of the above exception, another exception occurred:

Traceback (most recent call last):
  File "nodcast.py", line 5944, in <module>
    main()
  File "nodcast.py", line 5936, in main
    wrapper(start)
  File "/home/ahmad/miniconda3/lib/python3.8/curses/__init__.py", line 105, in wrapper
    return func(stdscr, *args, **kwds)
  File "nodcast.py", line 4919, in start
    show_files(save_folder, exts=['*.txt', '*.artid', "*.listid", '*.art','*.pdf','*.list','*.json','*.squad','*.prc'], extract=True)
  File "nodcast.py", line 5033, in show_files
    show_files(sfolder, exts, depth + 1)
  File "nodcast.py", line 5235, in show_files
    show_article(art)
  File "nodcast.py", line 2624, in show_article
    show_msg("Recording was canceled at" + str(rec_i), " his s again to resume")
  File "nodcast.py", line 4030, in show_msg
    show_info(msg, color)
  File "nodcast.py", line 3968, in show_info
    win_info.bkgd(' ', cur.color_pair(color))  # | cur.A_REVERSE)
TypeError: an integer is required (got type str)
CRITICAL:root:
Date:2021-06-07 19:19:01.289642
Traceback (most recent call last):
  File "nodcast.py", line 2619, in show_article
    record(sent["text"], "test", "sent_" + str(ii) )
  File "nodcast.py", line 1732, in record
    tts.save(sound_file)
  File "/home/ahmad/miniconda3/lib/python3.8/site-packages/gtts/tts.py", line 312, in save
    self.write_to_fp(f)
  File "/home/ahmad/miniconda3/lib/python3.8/site-packages/gtts/tts.py", line 263, in write_to_fp
    r = s.send(request=pr,
  File "/home/ahmad/miniconda3/lib/python3.8/site-packages/requests/sessions.py", line 643, in send
    r = adapter.send(request, **kwargs)
  File "/home/ahmad/miniconda3/lib/python3.8/site-packages/requests/adapters.py", line 439, in send
    resp = conn.urlopen(
  File "/home/ahmad/miniconda3/lib/python3.8/site-packages/urllib3/connectionpool.py", line 670, in urlopen
    httplib_response = self._make_request(
  File "/home/ahmad/miniconda3/lib/python3.8/site-packages/urllib3/connectionpool.py", line 426, in _make_request
    six.raise_from(e, None)
  File "<string>", line 3, in raise_from
  File "/home/ahmad/miniconda3/lib/python3.8/site-packages/urllib3/connectionpool.py", line 421, in _make_request
    httplib_response = conn.getresponse()
  File "/home/ahmad/miniconda3/lib/python3.8/http/client.py", line 1347, in getresponse
    response.begin()
  File "/home/ahmad/miniconda3/lib/python3.8/http/client.py", line 307, in begin
    version, status, reason = self._read_status()
  File "/home/ahmad/miniconda3/lib/python3.8/http/client.py", line 268, in _read_status
    line = str(self.fp.readline(_MAXLINE + 1), "iso-8859-1")
  File "/home/ahmad/miniconda3/lib/python3.8/socket.py", line 669, in readinto
    return self._sock.recv_into(b)
  File "/home/ahmad/miniconda3/lib/python3.8/ssl.py", line 1241, in recv_into
    return self.read(nbytes, buffer)
  File "/home/ahmad/miniconda3/lib/python3.8/ssl.py", line 1099, in read
    return self._sslobj.read(len, buffer)
KeyboardInterrupt

During handling of the above exception, another exception occurred:

Traceback (most recent call last):
  File "nodcast.py", line 5944, in <module>
    main()
  File "nodcast.py", line 5936, in main
    wrapper(start)
  File "/home/ahmad/miniconda3/lib/python3.8/curses/__init__.py", line 105, in wrapper
    return func(stdscr, *args, **kwds)
  File "nodcast.py", line 4919, in start
    show_files(save_folder, exts=['*.txt', '*.artid', "*.listid", '*.art','*.pdf','*.list','*.json','*.squad','*.prc'], extract=True)
  File "nodcast.py", line 5033, in show_files
    show_files(sfolder, exts, depth + 1)
  File "nodcast.py", line 5235, in show_files
    show_article(art)
  File "nodcast.py", line 2624, in show_article
    show_msg("Recording was canceled at" + str(rec_i), " his s again to resume")
  File "nodcast.py", line 4030, in show_msg
    show_info(msg, color)
  File "nodcast.py", line 3968, in show_info
    win_info.bkgd(' ', cur.color_pair(color))  # | cur.A_REVERSE)
TypeError: an integer is required (got type str)
CRITICAL:root:
Date:2021-06-07 19:22:03.096369
Traceback (most recent call last):
  File "nodcast.py", line 5943, in <module>
    main()
  File "nodcast.py", line 5935, in main
    wrapper(start)
  File "/home/ahmad/miniconda3/lib/python3.8/curses/__init__.py", line 105, in wrapper
    return func(stdscr, *args, **kwds)
  File "nodcast.py", line 4918, in start
    show_files(save_folder, exts=['*.txt', '*.artid', "*.listid", '*.art','*.pdf','*.list','*.json','*.squad','*.prc'], extract=True)
  File "nodcast.py", line 5032, in show_files
    show_files(sfolder, exts, depth + 1)
  File "nodcast.py", line 5234, in show_files
    show_article(art)
  File "nodcast.py", line 2618, in show_article
    record(sent["text"], "test", "sent_" + str(ii) )
  File "nodcast.py", line 1727, in record
    p = Path.home() + Path('rec_files/'+ sound_folder)
TypeError: unsupported operand type(s) for +: 'PosixPath' and 'PosixPath'
CRITICAL:root:
Date:2021-06-07 19:25:19.552653
Traceback (most recent call last):
  File "nodcast.py", line 2617, in show_article
    record(sent["text"], "test", "sent_" + str(ii) )
  File "nodcast.py", line 1730, in record
    tts.save(sound_file)
  File "/home/ahmad/miniconda3/lib/python3.8/site-packages/gtts/tts.py", line 312, in save
    self.write_to_fp(f)
  File "/home/ahmad/miniconda3/lib/python3.8/site-packages/gtts/tts.py", line 263, in write_to_fp
    r = s.send(request=pr,
  File "/home/ahmad/miniconda3/lib/python3.8/site-packages/requests/sessions.py", line 643, in send
    r = adapter.send(request, **kwargs)
  File "/home/ahmad/miniconda3/lib/python3.8/site-packages/requests/adapters.py", line 439, in send
    resp = conn.urlopen(
  File "/home/ahmad/miniconda3/lib/python3.8/site-packages/urllib3/connectionpool.py", line 670, in urlopen
    httplib_response = self._make_request(
  File "/home/ahmad/miniconda3/lib/python3.8/site-packages/urllib3/connectionpool.py", line 381, in _make_request
    self._validate_conn(conn)
  File "/home/ahmad/miniconda3/lib/python3.8/site-packages/urllib3/connectionpool.py", line 978, in _validate_conn
    conn.connect()
  File "/home/ahmad/miniconda3/lib/python3.8/site-packages/urllib3/connection.py", line 309, in connect
    conn = self._new_conn()
  File "/home/ahmad/miniconda3/lib/python3.8/site-packages/urllib3/connection.py", line 159, in _new_conn
    conn = connection.create_connection(
  File "/home/ahmad/miniconda3/lib/python3.8/site-packages/urllib3/util/connection.py", line 74, in create_connection
    sock.connect(sa)
KeyboardInterrupt

During handling of the above exception, another exception occurred:

Traceback (most recent call last):
  File "nodcast.py", line 5942, in <module>
    main()
  File "nodcast.py", line 5934, in main
    wrapper(start)
  File "/home/ahmad/miniconda3/lib/python3.8/curses/__init__.py", line 105, in wrapper
    return func(stdscr, *args, **kwds)
  File "nodcast.py", line 4917, in start
    show_files(save_folder, exts=['*.txt', '*.artid', "*.listid", '*.art','*.pdf','*.list','*.json','*.squad','*.prc'], extract=True)
  File "nodcast.py", line 5031, in show_files
    show_files(sfolder, exts, depth + 1)
  File "nodcast.py", line 5233, in show_files
    show_article(art)
  File "nodcast.py", line 2622, in show_article
    show_msg("Recording was canceled at" + str(rec_i), " his s again to resume")
  File "nodcast.py", line 4028, in show_msg
    show_info(msg, color)
  File "nodcast.py", line 3966, in show_info
    win_info.bkgd(' ', cur.color_pair(color))  # | cur.A_REVERSE)
TypeError: an integer is required (got type str)
CRITICAL:root:
Date:2021-06-07 19:26:54.170011
Traceback (most recent call last):
  File "nodcast.py", line 2618, in show_article
    record(sent["text"], "test", "sent_" + str(ii) )
  File "nodcast.py", line 1730, in record
    show_msg(sound_file)
  File "nodcast.py", line 4032, in show_msg
    std.getch()
KeyboardInterrupt

During handling of the above exception, another exception occurred:

Traceback (most recent call last):
  File "nodcast.py", line 5943, in <module>
    main()
  File "nodcast.py", line 5935, in main
    wrapper(start)
  File "/home/ahmad/miniconda3/lib/python3.8/curses/__init__.py", line 105, in wrapper
    return func(stdscr, *args, **kwds)
  File "nodcast.py", line 4918, in start
    show_files(save_folder, exts=['*.txt', '*.artid', "*.listid", '*.art','*.pdf','*.list','*.json','*.squad','*.prc'], extract=True)
  File "nodcast.py", line 5032, in show_files
    show_files(sfolder, exts, depth + 1)
  File "nodcast.py", line 5234, in show_files
    show_article(art)
  File "nodcast.py", line 2623, in show_article
    show_msg("Recording was canceled at" + str(rec_i), " his s again to resume")
  File "nodcast.py", line 4029, in show_msg
    show_info(msg, color)
  File "nodcast.py", line 3967, in show_info
    win_info.bkgd(' ', cur.color_pair(color))  # | cur.A_REVERSE)
TypeError: an integer is required (got type str)
CRITICAL:root:
Date:2021-06-07 21:57:28.195505
Traceback (most recent call last):
  File "/home/ahmad/miniconda3/lib/python3.8/site-packages/urllib3/connection.py", line 159, in _new_conn
    conn = connection.create_connection(
  File "/home/ahmad/miniconda3/lib/python3.8/site-packages/urllib3/util/connection.py", line 61, in create_connection
    for res in socket.getaddrinfo(host, port, family, socket.SOCK_STREAM):
  File "/home/ahmad/miniconda3/lib/python3.8/socket.py", line 918, in getaddrinfo
    for res in _socket.getaddrinfo(host, port, family, type, proto, flags):
socket.gaierror: [Errno -3] Temporary failure in name resolution

During handling of the above exception, another exception occurred:

Traceback (most recent call last):
  File "/home/ahmad/miniconda3/lib/python3.8/site-packages/urllib3/connectionpool.py", line 670, in urlopen
    httplib_response = self._make_request(
  File "/home/ahmad/miniconda3/lib/python3.8/site-packages/urllib3/connectionpool.py", line 381, in _make_request
    self._validate_conn(conn)
  File "/home/ahmad/miniconda3/lib/python3.8/site-packages/urllib3/connectionpool.py", line 978, in _validate_conn
    conn.connect()
  File "/home/ahmad/miniconda3/lib/python3.8/site-packages/urllib3/connection.py", line 309, in connect
    conn = self._new_conn()
  File "/home/ahmad/miniconda3/lib/python3.8/site-packages/urllib3/connection.py", line 171, in _new_conn
    raise NewConnectionError(
urllib3.exceptions.NewConnectionError: <urllib3.connection.HTTPSConnection object at 0x7f784b485b80>: Failed to establish a new connection: [Errno -3] Temporary failure in name resolution

During handling of the above exception, another exception occurred:

Traceback (most recent call last):
  File "/home/ahmad/miniconda3/lib/python3.8/site-packages/requests/adapters.py", line 439, in send
    resp = conn.urlopen(
  File "/home/ahmad/miniconda3/lib/python3.8/site-packages/urllib3/connectionpool.py", line 726, in urlopen
    retries = retries.increment(
  File "/home/ahmad/miniconda3/lib/python3.8/site-packages/urllib3/util/retry.py", line 439, in increment
    raise MaxRetryError(_pool, url, error or ResponseError(cause))
urllib3.exceptions.MaxRetryError: HTTPSConnectionPool(host='translate.google.com', port=443): Max retries exceeded with url: /_/TranslateWebserverUi/data/batchexecute (Caused by NewConnectionError('<urllib3.connection.HTTPSConnection object at 0x7f784b485b80>: Failed to establish a new connection: [Errno -3] Temporary failure in name resolution'))

During handling of the above exception, another exception occurred:

Traceback (most recent call last):
  File "/home/ahmad/miniconda3/lib/python3.8/site-packages/gtts/tts.py", line 263, in write_to_fp
    r = s.send(request=pr,
  File "/home/ahmad/miniconda3/lib/python3.8/site-packages/requests/sessions.py", line 643, in send
    r = adapter.send(request, **kwargs)
  File "/home/ahmad/miniconda3/lib/python3.8/site-packages/requests/adapters.py", line 516, in send
    raise ConnectionError(e, request=request)
requests.exceptions.ConnectionError: HTTPSConnectionPool(host='translate.google.com', port=443): Max retries exceeded with url: /_/TranslateWebserverUi/data/batchexecute (Caused by NewConnectionError('<urllib3.connection.HTTPSConnection object at 0x7f784b485b80>: Failed to establish a new connection: [Errno -3] Temporary failure in name resolution'))

During handling of the above exception, another exception occurred:

Traceback (most recent call last):
  File "nodcast.py", line 5948, in <module>
    main()
  File "nodcast.py", line 5940, in main
    wrapper(start)
  File "/home/ahmad/miniconda3/lib/python3.8/curses/__init__.py", line 105, in wrapper
    return func(stdscr, *args, **kwds)
  File "nodcast.py", line 4912, in start
    list_articles(last_visited, "Recent Articles", group="last_visited")
  File "nodcast.py", line 1102, in list_articles
    show_article(articles[k])
  File "nodcast.py", line 2620, in show_article
    sfile = record(sent["text"], art["title"], f"sent_{ii:03d}")
  File "nodcast.py", line 1732, in record
    tts.save(sound_file)
  File "/home/ahmad/miniconda3/lib/python3.8/site-packages/gtts/tts.py", line 312, in save
    self.write_to_fp(f)
  File "/home/ahmad/miniconda3/lib/python3.8/site-packages/gtts/tts.py", line 279, in write_to_fp
    raise gTTSError(tts=self)
gtts.tts.gTTSError: Failed to connect. Probable cause: Unknown
CRITICAL:root:
Date:2021-06-07 21:59:41.695557
Traceback (most recent call last):
  File "/home/ahmad/miniconda3/lib/python3.8/site-packages/urllib3/connection.py", line 159, in _new_conn
    conn = connection.create_connection(
  File "/home/ahmad/miniconda3/lib/python3.8/site-packages/urllib3/util/connection.py", line 61, in create_connection
    for res in socket.getaddrinfo(host, port, family, socket.SOCK_STREAM):
  File "/home/ahmad/miniconda3/lib/python3.8/socket.py", line 918, in getaddrinfo
    for res in _socket.getaddrinfo(host, port, family, type, proto, flags):
socket.gaierror: [Errno -3] Temporary failure in name resolution

During handling of the above exception, another exception occurred:

Traceback (most recent call last):
  File "/home/ahmad/miniconda3/lib/python3.8/site-packages/urllib3/connectionpool.py", line 670, in urlopen
    httplib_response = self._make_request(
  File "/home/ahmad/miniconda3/lib/python3.8/site-packages/urllib3/connectionpool.py", line 381, in _make_request
    self._validate_conn(conn)
  File "/home/ahmad/miniconda3/lib/python3.8/site-packages/urllib3/connectionpool.py", line 978, in _validate_conn
    conn.connect()
  File "/home/ahmad/miniconda3/lib/python3.8/site-packages/urllib3/connection.py", line 309, in connect
    conn = self._new_conn()
  File "/home/ahmad/miniconda3/lib/python3.8/site-packages/urllib3/connection.py", line 171, in _new_conn
    raise NewConnectionError(
urllib3.exceptions.NewConnectionError: <urllib3.connection.HTTPSConnection object at 0x7fd4894b17f0>: Failed to establish a new connection: [Errno -3] Temporary failure in name resolution

During handling of the above exception, another exception occurred:

Traceback (most recent call last):
  File "/home/ahmad/miniconda3/lib/python3.8/site-packages/requests/adapters.py", line 439, in send
    resp = conn.urlopen(
  File "/home/ahmad/miniconda3/lib/python3.8/site-packages/urllib3/connectionpool.py", line 726, in urlopen
    retries = retries.increment(
  File "/home/ahmad/miniconda3/lib/python3.8/site-packages/urllib3/util/retry.py", line 439, in increment
    raise MaxRetryError(_pool, url, error or ResponseError(cause))
urllib3.exceptions.MaxRetryError: HTTPSConnectionPool(host='translate.google.com', port=443): Max retries exceeded with url: /_/TranslateWebserverUi/data/batchexecute (Caused by NewConnectionError('<urllib3.connection.HTTPSConnection object at 0x7fd4894b17f0>: Failed to establish a new connection: [Errno -3] Temporary failure in name resolution'))

During handling of the above exception, another exception occurred:

Traceback (most recent call last):
  File "/home/ahmad/miniconda3/lib/python3.8/site-packages/gtts/tts.py", line 263, in write_to_fp
    r = s.send(request=pr,
  File "/home/ahmad/miniconda3/lib/python3.8/site-packages/requests/sessions.py", line 643, in send
    r = adapter.send(request, **kwargs)
  File "/home/ahmad/miniconda3/lib/python3.8/site-packages/requests/adapters.py", line 516, in send
    raise ConnectionError(e, request=request)
requests.exceptions.ConnectionError: HTTPSConnectionPool(host='translate.google.com', port=443): Max retries exceeded with url: /_/TranslateWebserverUi/data/batchexecute (Caused by NewConnectionError('<urllib3.connection.HTTPSConnection object at 0x7fd4894b17f0>: Failed to establish a new connection: [Errno -3] Temporary failure in name resolution'))

During handling of the above exception, another exception occurred:

Traceback (most recent call last):
  File "nodcast.py", line 2620, in show_article
    sfile = record(sent["text"], art["title"], f"sent_{ii:03d}")
  File "nodcast.py", line 1732, in record
    tts.save(sound_file)
  File "/home/ahmad/miniconda3/lib/python3.8/site-packages/gtts/tts.py", line 312, in save
    self.write_to_fp(f)
  File "/home/ahmad/miniconda3/lib/python3.8/site-packages/gtts/tts.py", line 279, in write_to_fp
    raise gTTSError(tts=self)
gtts.tts.gTTSError: Failed to connect. Probable cause: Unknown

During handling of the above exception, another exception occurred:

Traceback (most recent call last):
  File "nodcast.py", line 5950, in <module>
    main()
  File "nodcast.py", line 5942, in main
    wrapper(start)
  File "/home/ahmad/miniconda3/lib/python3.8/curses/__init__.py", line 105, in wrapper
    return func(stdscr, *args, **kwds)
  File "nodcast.py", line 4925, in start
    show_files(save_folder, exts=['*.txt', '*.artid', "*.listid", '*.art','*.pdf','*.list','*.json','*.squad','*.prc'], extract=True)
  File "nodcast.py", line 5039, in show_files
    show_files(sfolder, exts, depth + 1)
  File "nodcast.py", line 5241, in show_files
    show_article(art)
  File "nodcast.py", line 2623, in show_article
    except gtts.tts.gTTSError:
NameError: name 'gtts' is not defined
CRITICAL:root:
Date:2021-06-07 22:54:35.253263
Traceback (most recent call last):
  File "/home/ahmad/miniconda3/lib/python3.8/site-packages/urllib3/connection.py", line 159, in _new_conn
    conn = connection.create_connection(
  File "/home/ahmad/miniconda3/lib/python3.8/site-packages/urllib3/util/connection.py", line 61, in create_connection
    for res in socket.getaddrinfo(host, port, family, socket.SOCK_STREAM):
  File "/home/ahmad/miniconda3/lib/python3.8/socket.py", line 918, in getaddrinfo
    for res in _socket.getaddrinfo(host, port, family, type, proto, flags):
socket.gaierror: [Errno -3] Temporary failure in name resolution

During handling of the above exception, another exception occurred:

Traceback (most recent call last):
  File "/home/ahmad/miniconda3/lib/python3.8/site-packages/urllib3/connectionpool.py", line 670, in urlopen
    httplib_response = self._make_request(
  File "/home/ahmad/miniconda3/lib/python3.8/site-packages/urllib3/connectionpool.py", line 381, in _make_request
    self._validate_conn(conn)
  File "/home/ahmad/miniconda3/lib/python3.8/site-packages/urllib3/connectionpool.py", line 978, in _validate_conn
    conn.connect()
  File "/home/ahmad/miniconda3/lib/python3.8/site-packages/urllib3/connection.py", line 309, in connect
    conn = self._new_conn()
  File "/home/ahmad/miniconda3/lib/python3.8/site-packages/urllib3/connection.py", line 171, in _new_conn
    raise NewConnectionError(
urllib3.exceptions.NewConnectionError: <urllib3.connection.HTTPSConnection object at 0x7fa50f403550>: Failed to establish a new connection: [Errno -3] Temporary failure in name resolution

During handling of the above exception, another exception occurred:

Traceback (most recent call last):
  File "/home/ahmad/miniconda3/lib/python3.8/site-packages/requests/adapters.py", line 439, in send
    resp = conn.urlopen(
  File "/home/ahmad/miniconda3/lib/python3.8/site-packages/urllib3/connectionpool.py", line 726, in urlopen
    retries = retries.increment(
  File "/home/ahmad/miniconda3/lib/python3.8/site-packages/urllib3/util/retry.py", line 439, in increment
    raise MaxRetryError(_pool, url, error or ResponseError(cause))
urllib3.exceptions.MaxRetryError: HTTPSConnectionPool(host='translate.google.com', port=443): Max retries exceeded with url: /_/TranslateWebserverUi/data/batchexecute (Caused by NewConnectionError('<urllib3.connection.HTTPSConnection object at 0x7fa50f403550>: Failed to establish a new connection: [Errno -3] Temporary failure in name resolution'))

During handling of the above exception, another exception occurred:

Traceback (most recent call last):
  File "/home/ahmad/miniconda3/lib/python3.8/site-packages/gtts/tts.py", line 263, in write_to_fp
    r = s.send(request=pr,
  File "/home/ahmad/miniconda3/lib/python3.8/site-packages/requests/sessions.py", line 643, in send
    r = adapter.send(request, **kwargs)
  File "/home/ahmad/miniconda3/lib/python3.8/site-packages/requests/adapters.py", line 516, in send
    raise ConnectionError(e, request=request)
requests.exceptions.ConnectionError: HTTPSConnectionPool(host='translate.google.com', port=443): Max retries exceeded with url: /_/TranslateWebserverUi/data/batchexecute (Caused by NewConnectionError('<urllib3.connection.HTTPSConnection object at 0x7fa50f403550>: Failed to establish a new connection: [Errno -3] Temporary failure in name resolution'))

During handling of the above exception, another exception occurred:

Traceback (most recent call last):
  File "nodcast.py", line 5952, in <module>
    main()
  File "nodcast.py", line 5944, in main
    wrapper(start)
  File "/home/ahmad/miniconda3/lib/python3.8/curses/__init__.py", line 105, in wrapper
    return func(stdscr, *args, **kwds)
  File "nodcast.py", line 4927, in start
    show_files(save_folder, exts=['*.txt', '*.artid', "*.listid", '*.art','*.pdf','*.list','*.json','*.squad','*.prc'], extract=True)
  File "nodcast.py", line 5041, in show_files
    show_files(sfolder, exts, depth + 1)
  File "nodcast.py", line 5243, in show_files
    show_article(art)
  File "nodcast.py", line 2931, in show_article
    sfile = record(cur_sent["text"], art["title"], f"sent_{bmark:03d}")
  File "nodcast.py", line 1733, in record
    tts.save(sound_file)
  File "/home/ahmad/miniconda3/lib/python3.8/site-packages/gtts/tts.py", line 312, in save
    self.write_to_fp(f)
  File "/home/ahmad/miniconda3/lib/python3.8/site-packages/gtts/tts.py", line 279, in write_to_fp
    raise gTTSError(tts=self)
gtts.tts.gTTSError: Failed to connect. Probable cause: Unknown
CRITICAL:root:
Date:2021-06-07 23:35:54.414354
Traceback (most recent call last):
  File "/home/ahmad/recs/nodcast/nodcast/nodcast.py", line 27, in <module>
    from nodcast.util import *
ModuleNotFoundError: No module named 'nodcast.util'; 'nodcast' is not a package

During handling of the above exception, another exception occurred:

Traceback (most recent call last):
  File "nodcast.py", line 27, in <module>
    from nodcast.util import *
  File "/home/ahmad/recs/nodcast/nodcast/nodcast.py", line 29, in <module>
    from util import *
  File "/home/ahmad/recs/nodcast/nodcast/util.py", line 183, in <module>
    from nodcast import HL_COLOR, WARNING_COLOR
ImportError: cannot import name 'HL_COLOR' from partially initialized module 'nodcast' (most likely due to a circular import) (/home/ahmad/recs/nodcast/nodcast/nodcast.py)

During handling of the above exception, another exception occurred:

Traceback (most recent call last):
  File "nodcast.py", line 29, in <module>
    from util import *
  File "/home/ahmad/recs/nodcast/nodcast/util.py", line 183, in <module>
    from nodcast import HL_COLOR, WARNING_COLOR
  File "/home/ahmad/recs/nodcast/nodcast/nodcast.py", line 1745, in <module>
    from pygame import mixer
ModuleNotFoundError: No module named 'pygame'
CRITICAL:root:
Date:2021-06-07 23:49:51.888552
Traceback (most recent call last):
  File "nodcast.py", line 5971, in <module>
    main()
  File "nodcast.py", line 5963, in main
    wrapper(start)
  File "/home/ahmad/miniconda3/lib/python3.8/curses/__init__.py", line 105, in wrapper
    return func(stdscr, *args, **kwds)
  File "nodcast.py", line 4946, in start
    show_files(save_folder, exts=['*.txt', '*.artid', "*.listid", '*.art','*.pdf','*.list','*.json','*.squad','*.prc'], extract=True)
  File "nodcast.py", line 5060, in show_files
    show_files(sfolder, exts, depth + 1)
  File "nodcast.py", line 5262, in show_files
    show_article(art)
  File "nodcast.py", line 2628, in show_article
    play(sfile)
  File "nodcast.py", line 1748, in play
    pygame.mixer.music.load(sound_file)
pygame.error: Unrecognized audio format
CRITICAL:root:
Date:2021-06-07 23:50:34.035854
Traceback (most recent call last):
  File "nodcast.py", line 5972, in <module>
    main()
  File "nodcast.py", line 5964, in main
    wrapper(start)
  File "/home/ahmad/miniconda3/lib/python3.8/curses/__init__.py", line 105, in wrapper
    return func(stdscr, *args, **kwds)
  File "nodcast.py", line 4947, in start
    show_files(save_folder, exts=['*.txt', '*.artid', "*.listid", '*.art','*.pdf','*.list','*.json','*.squad','*.prc'], extract=True)
  File "nodcast.py", line 5061, in show_files
    show_files(sfolder, exts, depth + 1)
  File "nodcast.py", line 5263, in show_files
    show_article(art)
  File "nodcast.py", line 2629, in show_article
    play(sfile)
  File "nodcast.py", line 1749, in play
    pygame.mixer.music.load(sound_file)
pygame.error: Unrecognized audio format
CRITICAL:root:
Date:2021-06-07 23:55:42.219465
Traceback (most recent call last):
  File "/home/ahmad/recs/nodcast/nodcast/nodcast.py", line 27, in <module>
    from nodcast.util import *
ModuleNotFoundError: No module named 'nodcast.util'; 'nodcast' is not a package

During handling of the above exception, another exception occurred:

Traceback (most recent call last):
  File "nodcast.py", line 27, in <module>
    from nodcast.util import *
  File "/home/ahmad/recs/nodcast/nodcast/nodcast.py", line 29, in <module>
    from util import *
  File "/home/ahmad/recs/nodcast/nodcast/util.py", line 183, in <module>
    from nodcast import HL_COLOR, WARNING_COLOR
ImportError: cannot import name 'HL_COLOR' from partially initialized module 'nodcast' (most likely due to a circular import) (/home/ahmad/recs/nodcast/nodcast/nodcast.py)

During handling of the above exception, another exception occurred:

Traceback (most recent call last):
  File "nodcast.py", line 29, in <module>
    from util import *
  File "/home/ahmad/recs/nodcast/nodcast/util.py", line 183, in <module>
    from nodcast import HL_COLOR, WARNING_COLOR
  File "/home/ahmad/recs/nodcast/nodcast/nodcast.py", line 1745, in <module>
    import vlc
ModuleNotFoundError: No module named 'vlc'
CRITICAL:root:
Date:2021-06-08 00:02:12.775889
Traceback (most recent call last):
  File "nodcast.py", line 5973, in <module>
    main()
  File "nodcast.py", line 5965, in main
    wrapper(start)
  File "/home/ahmad/miniconda3/lib/python3.8/curses/__init__.py", line 105, in wrapper
    return func(stdscr, *args, **kwds)
  File "nodcast.py", line 4937, in start
    list_articles(last_visited, "Recent Articles", group="last_visited")
  File "nodcast.py", line 1103, in list_articles
    show_article(articles[k])
  File "nodcast.py", line 2630, in show_article
    play(sfile)
  File "nodcast.py", line 1751, in play
    p.play()
NameError: name 'p' is not defined
CRITICAL:root:
Date:2021-06-08 00:29:50.527148
Traceback (most recent call last):
  File "nodcast.py", line 5973, in <module>
    if ret != "":
  File "nodcast.py", line 5965, in main
    if fsize > 24:
  File "/home/ahmad/miniconda3/lib/python3.8/curses/__init__.py", line 105, in wrapper
    return func(stdscr, *args, **kwds)
  File "nodcast.py", line 4937, in start
    elif ch == 'w' or ch == "website articles":
  File "nodcast.py", line 1103, in list_articles
    show_article(articles[k])
  File "nodcast.py", line 3316, in show_article
    dif = total_sents - old_total_sents
ValueError: chr() arg not in range(0x110000)
CRITICAL:root:
Date:2021-06-08 10:02:37.183051
Traceback (most recent call last):
  File "nodcast.py", line 6001, in <module>
    main()
  File "nodcast.py", line 5993, in main
    wrapper(start)
  File "/home/ahmad/miniconda3/lib/python3.8/curses/__init__.py", line 105, in wrapper
    return func(stdscr, *args, **kwds)
  File "nodcast.py", line 4965, in start
    list_articles(last_visited, "Recent Articles", group="last_visited")
  File "nodcast.py", line 1103, in list_articles
    show_article(articles[k])
  File "nodcast.py", line 3435, in show_article
    if ord(ch) == "S":
TypeError: ord() expected string of length 1, but int found
CRITICAL:root:
Date:2021-06-08 10:03:30.989634
Traceback (most recent call last):
  File "nodcast.py", line 6001, in <module>
    main()
  File "nodcast.py", line 5993, in main
    wrapper(start)
  File "/home/ahmad/miniconda3/lib/python3.8/curses/__init__.py", line 105, in wrapper
    return func(stdscr, *args, **kwds)
  File "nodcast.py", line 4965, in start
    list_articles(last_visited, "Recent Articles", group="last_visited")
  File "nodcast.py", line 1103, in list_articles
    show_article(articles[k])
  File "nodcast.py", line 3438, in show_article
    for frag in sect["sections"]["fragments"]:
KeyError: 'sections'
CRITICAL:root:
Date:2021-06-08 10:48:44.940430
Traceback (most recent call last):
  File "nodcast.py", line 6010, in <module>
    main()
  File "nodcast.py", line 6002, in main
    wrapper(start)
  File "/home/ahmad/miniconda3/lib/python3.8/curses/__init__.py", line 105, in wrapper
    return func(stdscr, *args, **kwds)
  File "nodcast.py", line 4985, in start
    show_files(save_folder, exts=['*.txt', '*.artid', "*.listid", '*.art','*.pdf','*.list','*.json','*.squad','*.prc'], extract=True)
  File "nodcast.py", line 5099, in show_files
    show_files(sfolder, exts, depth + 1)
  File "nodcast.py", line 5301, in show_files
    show_article(art)
  File "nodcast.py", line 2639, in show_article
    show_info("Recording ... sentence " + ("#"* ii//10) + str(ii))
TypeError: unsupported operand type(s) for //: 'str' and 'int'
CRITICAL:root:
Date:2021-06-08 11:14:46.335579
Traceback (most recent call last):
  File "nodcast.py", line 6018, in <module>
    main()
  File "nodcast.py", line 6010, in main
    wrapper(start)
  File "/home/ahmad/miniconda3/lib/python3.8/curses/__init__.py", line 105, in wrapper
    return func(stdscr, *args, **kwds)
  File "nodcast.py", line 4993, in start
    show_files(save_folder, exts=['*.txt', '*.artid', "*.listid", '*.art','*.pdf','*.list','*.json','*.squad','*.prc'], extract=True)
  File "nodcast.py", line 5107, in show_files
    show_files(sfolder, exts, depth + 1)
  File "nodcast.py", line 5309, in show_files
    show_article(art)
  File "nodcast.py", line 2961, in show_article
    elif sound_enabled:
UnboundLocalError: local variable 'sound_enabled' referenced before assignment
CRITICAL:root:
Date:2021-06-08 11:47:34.830160
Traceback (most recent call last):
  File "nodcast.py", line 6022, in <module>
    main()
  File "nodcast.py", line 6014, in main
    wrapper(start)
  File "/home/ahmad/miniconda3/lib/python3.8/curses/__init__.py", line 105, in wrapper
    return func(stdscr, *args, **kwds)
  File "nodcast.py", line 4997, in start
    show_files(save_folder, exts=['*.txt', '*.artid', "*.listid", '*.art','*.pdf','*.list','*.json','*.squad','*.prc'], extract=True)
  File "nodcast.py", line 5283, in show_files
    show_article(art)
  File "nodcast.py", line 2645, in show_article
    if not f_exiddst:
NameError: name 'f_exiddst' is not defined
CRITICAL:root:
Date:2021-06-08 14:11:10.057589
Traceback (most recent call last):
  File "nodcast.py", line 6030, in <module>
    main()
  File "nodcast.py", line 6022, in main
    wrapper(start)
  File "/home/ahmad/miniconda3/lib/python3.8/curses/__init__.py", line 105, in wrapper
    return func(stdscr, *args, **kwds)
  File "nodcast.py", line 5005, in start
    show_files(save_folder, exts=['*.txt', '*.artid', "*.listid", '*.art','*.pdf','*.list','*.json','*.squad','*.prc'], extract=True)
  File "nodcast.py", line 5119, in show_files
    show_files(sfolder, exts, depth + 1)
  File "nodcast.py", line 5321, in show_files
    show_article(art)
  File "nodcast.py", line 3642, in show_article
    if not art in saved_articles and not art_inserted:
TypeError: unhashable type: 'dict'
CRITICAL:root:
Date:2021-06-08 18:55:34.755068
Traceback (most recent call last):
  File "nodcast.py", line 6036, in <module>
    main()
  File "nodcast.py", line 6028, in main
    wrapper(start)
  File "/home/ahmad/miniconda3/lib/python3.8/curses/__init__.py", line 105, in wrapper
    return func(stdscr, *args, **kwds)
  File "nodcast.py", line 5011, in start
    show_files(save_folder, exts=['*.txt', '*.artid', "*.listid", '*.art','*.pdf','*.list','*.json','*.squad','*.prc'], extract=True)
  File "nodcast.py", line 5125, in show_files
    show_files(sfolder, exts, depth + 1)
  File "nodcast.py", line 5327, in show_files
    show_article(art)
  File "nodcast.py", line 2650, in show_article
    record(sent["text"], sfile)
  File "nodcast.py", line 1742, in record
    show_msg(text, bottom=False, delay=-1)
TypeError: show_msg() got an unexpected keyword argument 'bottom'
CRITICAL:root:
Date:2021-06-08 18:56:29.803415
Traceback (most recent call last):
  File "nodcast.py", line 6036, in <module>
    main()
  File "nodcast.py", line 6028, in main
    wrapper(start)
  File "/home/ahmad/miniconda3/lib/python3.8/curses/__init__.py", line 105, in wrapper
    return func(stdscr, *args, **kwds)
  File "nodcast.py", line 5000, in start
    list_articles(last_visited, "Recent Articles", group="last_visited")
  File "nodcast.py", line 1103, in list_articles
    show_article(articles[k])
  File "nodcast.py", line 2650, in show_article
    record(sent["text"], sfile)
  File "nodcast.py", line 1742, in record
    show_err(text, bottom=False, delay=-1)
TypeError: show_err() got an unexpected keyword argument 'delay'
CRITICAL:root:
Date:2021-06-08 18:57:57.743887
Traceback (most recent call last):
  File "nodcast.py", line 6036, in <module>
    main()
  File "nodcast.py", line 6028, in main
    wrapper(start)
  File "/home/ahmad/miniconda3/lib/python3.8/curses/__init__.py", line 105, in wrapper
    return func(stdscr, *args, **kwds)
  File "nodcast.py", line 5000, in start
    list_articles(last_visited, "Recent Articles", group="last_visited")
  File "nodcast.py", line 1103, in list_articles
    show_article(articles[k])
  File "nodcast.py", line 3353, in show_article
    if chr(ch) in ['1','8','9','0','5','3'] or chr(ch) in ['!','*','(',')','=',' ',':']: #@@@
ValueError: chr() arg not in range(0x110000)
CRITICAL:root:weizhicheng1@huawei.com ============= Page 0 ==========
CRITICAL:root:Motivated by this, we propose to study the task of few-shot KG-to-text generation that aims to produce satisfactory output text given only a handful of (several hundred) labelled instances.
CRITICAL:root:To fulﬁl this task, we need to fully understand the complicated semantic relations between entities from various domains, which is challenging with limited labelled data.
CRITICAL:root:Our solution is inspired by the excellent few-shot capabilities of pretrained language models (PLMs) on language understanding and generation tasks (Brown et al., 2020; Chen et al., 2020; Li et al., 2021a).
CRITICAL:root:Pretrained on the large-scale corpora, PLMs encode vast amounts of world knowledge into their parameters (Li et al., 2021b), which is potentially beneﬁcial to understand and describe the KG facts in our task.
CRITICAL:root:However, applying PLMs to few-shot KG-totext generation still faces two challenges.
CRITICAL:root:First, PLMs are usually pretrained on natural language text, while the KG inputs for our task are structured graphs.
CRITICAL:root:This semantic gap makes it difﬁcult to effectively inject KG representations into PLMs especially with limited labelled instances.
CRITICAL:root:Second, unlike many other text generation tasks, KG-to-text generation requires faithful generation based on the understanding of KG facts.
CRITICAL:root:It needs to learn an accurate semantic correspondence between input ============= Page 1 ==========
CRITICAL:root:KG and output text, which will be more difﬁcult in few-shot settings.
CRITICAL:root:To address the above issues, in this paper, we propose a few-shot KG-to-text generation model based on PLMs. There are three major technical contributions in our model.
CRITICAL:root:First, in order to bridge the semantic gap, we enforce the representation alignment by learning the correspondence between KG representations (encoded by graph neural networks) and PLM-based entity representations.
CRITICAL:root:Second, to feed KG into PLMs, we propose a relation-biased breadth-ﬁrst search (RBFS) strategy to linearize KG into a well-planned entity sequence.
CRITICAL:root:Finally, we jointly train the primary text generation task and an auxiliary KG reconstruction task under the framework of multi-task learning.
CRITICAL:root:This step further enhances the semantic correspondence between input KG and output text, based on which our model can generate faithful text about KG.
CRITICAL:root:To the best of our knowledge, we are the ﬁrst study to investigate PLMs for few-shot KG-to-text generation.
CRITICAL:root:Extensive experiments on three benchmark datasets demonstrate the effectiveness of our few-shot KG-to-text generation model.
CRITICAL:root:In this work, we mainly focus on generating text from knowledge graphs using PLMs.
CRITICAL:root:KG-to-Text Generation.
CRITICAL:root:Early works mainly centered around statistical methods, applying grammar rules to generate text (Konstas and Lapata, 2013; Flanigan et al., 2016).
CRITICAL:root:Recently, neural based approaches have been proposed to generate text from linearized KG triples (Gardent et al., 2017), however, unable to model structural information about KG.
CRITICAL:root:Many works explored how to encode the graph structure using Graph Neural Networks (GNNs) or Transformers explicitly.
CRITICAL:root:Koncel-Kedziorski et al. (2019) leveraged a graph Transformer encoder to compute node representations by attending over local neighborhoods via self-attention.
CRITICAL:root:In contrast, Ribeiro et al. (2020a) focused on combining global and local message passing mechanisms based on GNNs, capturing complementary graph contexts.
CRITICAL:root:Guo et al. (2020) presented an unsupervised training method that can iteratively back translate between the text and graph data.
CRITICAL:root:Different from them, we explore how to utilize large PLMs for few-shot
CRITICAL:root:KG-to-text generation.
CRITICAL:root:Pretrained Language Model.
CRITICAL:root:Recent years have witnessed prominent achievement of PLMs in NLP tasks (Devlin et al., 2019; Radford et al., 2019).
CRITICAL:root:Pretrained on massive corpora, pretrained models showcase unprecedented generalization ability to solve related downstream tasks (Li et al., 2021b).
CRITICAL:root:However, most of existing PLMs were conditioned on text data (Radford et al., 2019; Lewis et al., 2020), lacking consideration of structured data input.
CRITICAL:root:Ribeiro et al. (2020b) proposed to utilize PLMs for KG-to-text generation by randomly linearizing graph into a sequence of triples.
CRITICAL:root:While, these methods do not explicitly model the structural relations of KG, which is critical for generating faithful text.
CRITICAL:root:Our work aims to consider the KG structure and bridge the semantic gap between KG encodings and PLMs.
CRITICAL:root:KG-to-text generation (Ribeiro et al., 2020a) aims to automatically generate a natural language text that describes the facts in KG.
CRITICAL:root:Formally, the input KG consists of a set of triples, denoted as G = {(cid:104)e, r, e(cid:48)(cid:105)|e, e(cid:48) ∈ E, r ∈ R}, where E and R denote the entity set and relation set, respectively.
CRITICAL:root:A triple (cid:104)e, r, e(cid:48)(cid:105) denotes the fact that relation r exists between head entity e and tail entity e(cid:48).
CRITICAL:root:Note that the input KG is a small and compact subgraph extracted from large-scale knowledge graphs (e.g., DBpedia).
CRITICAL:root:Following KoncelKedziorski et al. (2019), a text describing the input KG is usually available in this task.
CRITICAL:root:Let V denote the vocabulary.
CRITICAL:root:The target is to generate a natural language text Y = (cid:104)w1, ..., wj, ..., wT (cid:105)(wj ∈ V) that represents the correct and concise semantics of entities and their relations in the given knowledge graph.
CRITICAL:root:The text contains a set of entity mentions M = {me|me = (cid:104)e, se, oe(cid:105), e ∈ E}, where e is the target entity, se and oe are the start and end indices of this mention in text Y, respectively.
CRITICAL:root:In other words, (cid:104)wse, ..., woe(cid:105) specially corresponds to entity e. For entities with multiple mentions in text, we only keep the ﬁrst mention of each entity in M. By replacing each word of mentions with the token “[MASK]”, we can obtain a masked text, denoted as Y[mask], which is also taken as input for representation alignment in Section 4.1.
CRITICAL:root:In practice, it is difﬁcult to collect massive pairs of KG and its descriptive text for training.
CRITICAL:root:In this paper, we study the task of few-shot KG-to-text generation with a handful of training instances (e.g., 200 instances) based on a given PLM (e.g., GPT-2).
CRITICAL:root:============= Page 2 ==========
CRITICAL:root:For our task, two major challenges are how to learn effective input representations and capture the semantic correspondence between KG and text.
CRITICAL:root:To address the two challenges, we propose three major technical contributions, namely representation alignment between KG encodings and PLMs, relation-biased BFS strategy for KG linearization, and multi-task learning with KG reconstruction.
CRITICAL:root:Figure 2 presents an illustrative overview of our model.
CRITICAL:root:Next we will describe each part in detail.
CRITICAL:root:Unlike previous works (Ribeiro et al., 2020b; Yang et al., 2020) that directly transform KG into text sequence, we employ graph neural network (GNN) as knowledge graph encoder to explicitly encode entity relations in KG.
CRITICAL:root:Based on the input KG, GNN would produce a set of entity embeddings, which can be regarded as the input word embeddings of
CRITICAL:root:PLM for generating text.
CRITICAL:root:However, the GNN-based entity embeddings and the PLM-based word (entity) embeddings come from two distinct semantic spaces.
CRITICAL:root:To bridge such a semantic gap, we propose a representation alignment method to align the GNN-based and PLM-based entity embeddings in different semantic spaces.
CRITICAL:root:The GNN-based KG encoder aims to generate entity embeddings for KG.
CRITICAL:root:Let ve ∈ RdE denote the entity embedding for a general entity e in KG, where dE is the embedding size.
CRITICAL:root:In our work, the entity embeddings are shared across different KGs and initialized with pretrained KG embeddings (Yang et al., 2015).
CRITICAL:root:We apply RGCN (Schlichtkrull et al., 2018) to generate entity embeddings by leveraging multi-relational information in KG.
CRITICAL:root:Then, the embedding of entity e at the l + 1-th layer of R-GCN can be computed as: v(l+1) = σ( (cid:88) (cid:88)
CRITICAL:root:W (l) where W (l) are trainable matrices, and and W (l)
CRITICAL:root:Note that, we represent an entity as a set of nodes.
CRITICAL:root:For instance, the entity Iron Man in Figure 1 will be represented by two nodes: one for the token Iron and the other for the token Man.
CRITICAL:root:This would enhance the generalization ability of KG encoder on unseen entities, since it learns entity embeddings at the token level.
CRITICAL:root:To obtain the PLM-based entity embeddings, we feed the masked text Y[mask] into the text encoder, i.e., the lower layers of PLM.
CRITICAL:root:As shown in Figure 1, compared with short entity mentions, the masked text contains rich context information about entities.
CRITICAL:root:Therefore, similar to masked language model (Devlin et al., 2019), the embeddings of masked text can be computed as: (cid:104)ˆvw1, ..., ˆvwT (cid:105) = Lower-Layers(Y[mask]), (2) where the entity mention me corresponds to the embedding sequence (cid:104)ˆvwse, ..., ˆvwoe(cid:105) and the PLMbased entity embedding ˆve can be computed by an average pooling over this embedding sequence.
CRITICAL:root:============= Page 3 ==========
CRITICAL:root:To bridge the semantic gap, we model the representation alignment by minimizing the Euclidean distance in semantic space between the GNN-based and PLM-based entity embeddings as:
CRITICAL:root:LRA = (cid:107)˜ve − ˆve(cid:107)2, (3) (cid:88) where ˜ve and ˆve are GNN-based and PLM-based entity embeddings, respectively.
CRITICAL:root:With representation alignment, the GNN-based entity embeddings can be aligned with the PLMbased entity embeddings in semantic space, which enables us to effectively inject KG representations into PLM for improving generation quality.
CRITICAL:root:To feed the KG into decoder (i.e., the higher layers of PLM), we need to linearize KG into an entity sequence.
CRITICAL:root:Previous work (Yang et al., 2020; Ribeiro et al., 2020b) usually relies on random or pre-deﬁned rules, which is not ﬂexible to model KG structures.
CRITICAL:root:Here, we propose to utilize breadthﬁrst search (BFS) strategy to traverse KG.
CRITICAL:root:BFS, a graph traversal algorithm, starts at the root node and explores all the nodes at the present layer before moving on to the nodes at the next depth layer1.
CRITICAL:root:Here, we assume that nodes at the same layer potentially express relevant semantics and should be placed in close positions of the entity sequence.
CRITICAL:root:Furthermore, we observe that some relations are often lexicalized before others, e.g., the nationality of a person often precedes the birthplace in descriptive text.
CRITICAL:root:Considering such relation priority, in this paper, we propose a relation-biased breadth ﬁrst search (RBFS) strategy to traverse and linearize KG into entity sequence.
CRITICAL:root:Speciﬁcally, we ﬁrst compute RBFS weights αe(cid:48) for each entity e(cid:48) based on their relations as: αe(cid:48) = σ(˜v(cid:62) (4) where W (L) is a relation matrix from Eq.
CRITICAL:root:Then, for two sibling entities e(cid:48) and e(cid:48)(cid:48) at the same layer, we traverse e(cid:48) before e(cid:48)(cid:48) if αe(cid:48) is greater than αe(cid:48)(cid:48), and vice versa.
CRITICAL:root:Finally, through RBFS, we can obtain a linearized entity sequence taken as input of the decoder for text generation.
CRITICAL:root:After obtaining the linearized entity sequence, we next take it as input and perform text generation.
CRITICAL:root:Different from other text generation tasks, KG-totext generation aims to generate text reﬂecting the concise facts in KG.
CRITICAL:root:Inspired by Liu et al. (2019), we incorporate an auxiliary KG reconstruction task to reconstruct the facts in KG for learning the semantic correspondence between text and KG.
CRITICAL:root:The text generation task is performed upon the higher layers of PLM.
CRITICAL:root:The objective is to maximize the likelihood of the reference text, which is equivalent to minimize the negative log-likelihood as:
CRITICAL:root:LLM = − log pgen(wj|w1, ..., wj−1; G), (5) where pgen is the generative probability from PLM.
CRITICAL:root:Besides, in KG-to-text generation, some tokens in descriptive text correspond to KG entities shown in Figure 1.
CRITICAL:root:The ability to copy entities from KG would enrich the generated text content, which can be achieved by the pointer generator (See et al., 2017).
CRITICAL:root:By feeding the hidden states of PLM and the token embedding, the copy probability pj pj (6) where W1, W2, and bcopy are trainable parameters, vwj is the embedding of token wj, and sj is the j-th hidden state from the top layer of PLM.
CRITICAL:root:
Date:2021-06-10 11:41:14.307749
Traceback (most recent call last):
  File "nodcast.py", line 6035, in <module>
    main()
  File "nodcast.py", line 6027, in main
    wrapper(start)
  File "/home/ahmad/miniconda3/lib/python3.8/curses/__init__.py", line 105, in wrapper
    return func(stdscr, *args, **kwds)
  File "nodcast.py", line 5011, in start
    show_files(save_folder, exts=['*.txt', '*.artid', "*.listid", '*.art','*.pdf','*.list','*.json','*.squad','*.prc'], extract=True)
  File "nodcast.py", line 5124, in show_files
    show_files(sfolder, exts, depth + 1)
  File "nodcast.py", line 5326, in show_files
    show_article(art)
  File "nodcast.py", line 2660, in show_article
    play(sfile)
TypeError: play() missing 2 required positional arguments: 'sents' and 'art'
CRITICAL:root:
Date:2021-06-12 00:12:43.244721
Traceback (most recent call last):
  File "/home/ahmad/miniconda3/lib/python3.8/curses/__init__.py", line 105, in wrapper
    return func(stdscr, *args, **kwds)
  File "nodcast.py", line 5028, in start
    show_files(save_folder, exts=['*.txt', '*.artid', "*.listid", '*.art','*.pdf','*.list','*.json','*.squad','*.prc'], extract=True)
  File "nodcast.py", line 5313, in show_files
    show_article(art)
  File "nodcast.py", line 3370, in show_article
    if chr(ch) in ['1','8','9','0','5','3'] or chr(ch) in ['!','*','(',')','=',' ',':']: #@@@
ValueError: chr() arg not in range(0x110000)

During handling of the above exception, another exception occurred:

Traceback (most recent call last):
  File "nodcast.py", line 6052, in <module>
    main()
  File "nodcast.py", line 6044, in main
    wrapper(start)
  File "/home/ahmad/miniconda3/lib/python3.8/curses/__init__.py", line 111, in wrapper
    nocbreak()
_curses.error: nocbreak() returned ERR
CRITICAL:root:
Date:2021-06-15 11:18:55.346772
Traceback (most recent call last):
  File "nodcast.py", line 6050, in <module>
    main()
  File "nodcast.py", line 6042, in main
    wrapper(start)
  File "/home/ahmad/miniconda3/lib/python3.8/curses/__init__.py", line 105, in wrapper
    return func(stdscr, *args, **kwds)
  File "nodcast.py", line 5015, in start
    list_articles(last_visited, "Recent Articles", group="last_visited")
  File "nodcast.py", line 1100, in list_articles
    show_article(articles[k])
  File "nodcast.py", line 2669, in show_article
    if Path(sent["sfile"]).is_file():
KeyError: 'sfile'
CRITICAL:root:
Date:2021-06-15 12:40:48.520901
Traceback (most recent call last):
  File "nodcast.py", line 6050, in <module>
    main()
  File "nodcast.py", line 6042, in main
    wrapper(start)
  File "/home/ahmad/miniconda3/lib/python3.8/curses/__init__.py", line 105, in wrapper
    return func(stdscr, *args, **kwds)
  File "nodcast.py", line 5026, in start
    show_files(save_folder, exts=['*.txt', '*.artid', "*.listid", '*.art','*.pdf','*.list','*.json','*.squad','*.prc'], extract=True)
  File "nodcast.py", line 5139, in show_files
    show_files(sfolder, exts, depth + 1)
  File "nodcast.py", line 5341, in show_files
    show_article(art)
  File "nodcast.py", line 3335, in show_article
    text_content = extractText(pdf_fname)
NameError: name 'pdf_fname' is not defined
CRITICAL:root:
Date:2021-06-15 18:02:09.240690
Traceback (most recent call last):
  File "nodcast.py", line 6049, in <module>
    main()
  File "nodcast.py", line 6041, in main
    wrapper(start)
  File "/home/ahmad/miniconda3/lib/python3.8/curses/__init__.py", line 105, in wrapper
    return func(stdscr, *args, **kwds)
  File "nodcast.py", line 5014, in start
    list_artids(last_visited, "Recent Articles", group="last_visited")
  File "nodcast.py", line 947, in list_artids
    arts = list_articles(articles, fid, group=group)
  File "nodcast.py", line 1100, in list_articles
    show_article(articles[k])
  File "nodcast.py", line 3730, in show_article
    insert_article_list(last_visited, art)
  File "nodcast.py", line 793, in insert_article_list
    i = get_index(articles, art["id"])
  File "nodcast.py", line 762, in get_index
    if a["id"] == art["id"]:
TypeError: string indices must be integers
CRITICAL:root:
Date:2021-06-15 18:07:02.864936
Traceback (most recent call last):
  File "nodcast.py", line 6050, in <module>
    main()
  File "nodcast.py", line 6042, in main
    wrapper(start)
  File "/home/ahmad/miniconda3/lib/python3.8/curses/__init__.py", line 105, in wrapper
    return func(stdscr, *args, **kwds)
  File "nodcast.py", line 5015, in start
    list_artids(last_visited, "Recent Articles", group="last_visited")
  File "nodcast.py", line 947, in list_artids
    arts = list_articles(articles, fid, group=group)
  File "nodcast.py", line 1100, in list_articles
    show_article(articles[k])
  File "nodcast.py", line 3731, in show_article
    insert_article_list(last_visited, art)
  File "nodcast.py", line 793, in insert_article_list
    i = get_index(articles, art["id"])
  File "nodcast.py", line 762, in get_index
    if a["id"] == art["id"]:
TypeError: string indices must be integers
CRITICAL:root:
Date:2021-06-15 18:10:39.050028
Traceback (most recent call last):
  File "nodcast.py", line 6050, in <module>
    main()
  File "nodcast.py", line 6042, in main
    wrapper(start)
  File "/home/ahmad/miniconda3/lib/python3.8/curses/__init__.py", line 105, in wrapper
    return func(stdscr, *args, **kwds)
  File "nodcast.py", line 5026, in start
    show_files(save_folder, exts=['*.txt', '*.artid', "*.listid", '*.art','*.pdf','*.list','*.json','*.squad','*.prc'], extract=True)
  File "nodcast.py", line 5139, in show_files
    show_files(sfolder, exts, depth + 1)
  File "nodcast.py", line 5341, in show_files
    show_article(art)
  File "nodcast.py", line 3731, in show_article
    insert_article_list(last_visited, art)
  File "nodcast.py", line 793, in insert_article_list
    i = get_index(articles, art)
  File "nodcast.py", line 762, in get_index
    if a["id"] == art["id"]:
TypeError: string indices must be integers
CRITICAL:root:
Date:2021-06-15 18:26:03.955422
Traceback (most recent call last):
  File "nodcast.py", line 6050, in <module>
    main()
  File "nodcast.py", line 6042, in main
    wrapper(start)
  File "/home/ahmad/miniconda3/lib/python3.8/curses/__init__.py", line 105, in wrapper
    return func(stdscr, *args, **kwds)
  File "nodcast.py", line 5026, in start
    show_files(save_folder, exts=['*.txt', '*.artid', "*.listid", '*.art','*.pdf','*.list','*.json','*.squad','*.prc'], extract=True)
  File "nodcast.py", line 5139, in show_files
    show_files(sfolder, exts, depth + 1)
  File "nodcast.py", line 5311, in show_files
    show_article(art)
  File "nodcast.py", line 3731, in show_article
    insert_article_list(last_visited, art)
  File "nodcast.py", line 793, in insert_article_list
    i = get_index(articles, art)
  File "nodcast.py", line 762, in get_index
    if a["id"] == art["id"]:
TypeError: string indices must be integers
CRITICAL:root:
Date:2021-06-16 11:55:13.860791
Traceback (most recent call last):
  File "nodcast.py", line 6046, in <module>
    main()
  File "nodcast.py", line 6038, in main
    wrapper(start)
  File "/home/ahmad/miniconda3/lib/python3.8/curses/__init__.py", line 105, in wrapper
    return func(stdscr, *args, **kwds)
  File "nodcast.py", line 5011, in start
    list_artids(last_visited, "Recent Articles", group="last_visited")
  File "nodcast.py", line 946, in list_artids
    artids.append(art["id"])
TypeError: string indices must be integers
CRITICAL:root:
Date:2021-06-16 11:55:47.465458
Traceback (most recent call last):
  File "nodcast.py", line 6046, in <module>
    main()
  File "nodcast.py", line 6038, in main
    wrapper(start)
  File "/home/ahmad/miniconda3/lib/python3.8/curses/__init__.py", line 105, in wrapper
    return func(stdscr, *args, **kwds)
  File "nodcast.py", line 5011, in start
    list_artids(last_visited, "Recent Articles", group="last_visited")
  File "nodcast.py", line 946, in list_artids
    artids.append(art["id"])
TypeError: string indices must be integers
CRITICAL:root:
Date:2021-06-18 12:47:29.417539
Traceback (most recent call last):
  File "nodcast.py", line 6047, in <module>
    main()
  File "nodcast.py", line 6039, in main
    wrapper(start)
  File "/home/ahmad/miniconda3/lib/python3.8/curses/__init__.py", line 105, in wrapper
    return func(stdscr, *args, **kwds)
  File "nodcast.py", line 5023, in start
    show_files(save_folder, exts=['*.txt', '*.artid', "*.listid", '*.art','*.pdf','*.list','*.json','*.squad','*.prc'], extract=True)
  File "nodcast.py", line 5136, in show_files
    show_files(sfolder, exts, depth + 1)
  File "nodcast.py", line 5338, in show_files
    show_article(art)
  File "nodcast.py", line 3728, in show_article
    insert_article_list(last_visited, art)
  File "nodcast.py", line 793, in insert_article_list
    articles.remove(art["id"])
ValueError: list.remove(x): x not in list
CRITICAL:root:
Date:2021-06-18 12:58:51.203767
Traceback (most recent call last):
  File "nodcast.py", line 6053, in <module>
    main()
  File "nodcast.py", line 6045, in main
    wrapper(start)
  File "/home/ahmad/miniconda3/lib/python3.8/curses/__init__.py", line 105, in wrapper
    return func(stdscr, *args, **kwds)
  File "nodcast.py", line 5029, in start
    show_files(save_folder, exts=['*.txt', '*.artid', "*.listid", '*.art','*.pdf','*.list','*.json','*.squad','*.prc'], extract=True)
  File "nodcast.py", line 5142, in show_files
    show_files(sfolder, exts, depth + 1)
  File "nodcast.py", line 5344, in show_files
    show_article(art)
  File "nodcast.py", line 3371, in show_article
    if chr(ch) in ['1','8','9','0','5','3'] or chr(ch) in ['!','*','(',')','=',' ',':']: #@@@
ValueError: chr() arg not in range(0x110000)
CRITICAL:root:
Date:2021-06-18 13:30:23.140169
Traceback (most recent call last):
  File "nodcast.py", line 6054, in <module>
    main()
  File "nodcast.py", line 6046, in main
    wrapper(start)
  File "/home/ahmad/miniconda3/lib/python3.8/curses/__init__.py", line 105, in wrapper
    return func(stdscr, *args, **kwds)
  File "nodcast.py", line 5030, in start
    show_files(save_folder, exts=['*.txt', '*.artid', "*.listid", '*.art','*.pdf','*.list','*.json','*.squad','*.prc'], extract=True)
  File "nodcast.py", line 5143, in show_files
    show_files(sfolder, exts, depth + 1)
  File "nodcast.py", line 5345, in show_files
    show_article(art)
  File "nodcast.py", line 3735, in show_article
    insert_article_list(last_visited, art)
  File "nodcast.py", line 793, in insert_article_list
    articles.remove(art["id"])
ValueError: list.remove(x): x not in list
CRITICAL:root:
Date:2021-06-18 15:45:03.775705
Traceback (most recent call last):
  File "nodcast.py", line 6056, in <module>
    main()
  File "nodcast.py", line 6048, in main
    wrapper(start)
  File "/home/ahmad/miniconda3/lib/python3.8/curses/__init__.py", line 105, in wrapper
    return func(stdscr, *args, **kwds)
  File "nodcast.py", line 5032, in start
    show_files(save_folder, exts=['*.txt', '*.artid', "*.listid", '*.art','*.pdf','*.list','*.json','*.squad','*.prc'], extract=True)
  File "nodcast.py", line 5145, in show_files
    show_files(sfolder, exts, depth + 1)
  File "nodcast.py", line 5347, in show_files
    show_article(art)
  File "nodcast.py", line 3737, in show_article
    insert_article_list(last_visited, art)
  File "nodcast.py", line 793, in insert_article_list
    articles.remove(art["id"])
ValueError: list.remove(x): x not in list
CRITICAL:root:
Date:2021-06-25 21:42:45.668158
Traceback (most recent call last):
  File "nodcast.py", line 6072, in <module>
    main()
  File "nodcast.py", line 6064, in main
    wrapper(start)
  File "/home/ahmad/miniconda3/lib/python3.8/curses/__init__.py", line 105, in wrapper
    return func(stdscr, *args, **kwds)
  File "nodcast.py", line 5044, in start
    show_files(save_folder, exts=['*.txt','*.artid','*.art',"*.listid", '*.list','*.tag.art'], extract=True)
  File "nodcast.py", line 5345, in show_files
    list_articles(arts, fid = name, group=group)
  File "nodcast.py", line 1276, in list_articles
    write_article(art, folder)
  File "nodcast.py", line 1348, in write_article
    text = c['text']
KeyError: 'text'
CRITICAL:root:
Date:2021-06-25 23:14:33.518013
Traceback (most recent call last):
  File "nodcast.py", line 6074, in <module>
    main()
  File "nodcast.py", line 6066, in main
    wrapper(start)
  File "/home/ahmad/miniconda3/lib/python3.8/curses/__init__.py", line 105, in wrapper
    return func(stdscr, *args, **kwds)
  File "nodcast.py", line 5039, in start
    list_artids(last_visited, "Recent Articles", group="last_visited")
  File "nodcast.py", line 944, in list_artids
    arts = list_articles(articles, fid, group=group)
  File "nodcast.py", line 1098, in list_articles
    show_article(articles[k])
  File "nodcast.py", line 3353, in show_article
    text_content = extractText(pdf_fname)
NameError: name 'pdf_fname' is not defined
CRITICAL:root:
Date:2021-06-26 17:06:59.014510
Traceback (most recent call last):
  File "nodcast.py", line 6077, in <module>
    main()
  File "nodcast.py", line 6069, in main
    wrapper(start)
  File "/home/ahmad/miniconda3/lib/python3.8/curses/__init__.py", line 105, in wrapper
    return func(stdscr, *args, **kwds)
  File "nodcast.py", line 5053, in start
    show_files(save_folder, exts=['*.txt', '*.artid', "*.listid", '*.art','*.pdf','*.list','*.json','*.squad','*.prc'], extract=True)
  File "nodcast.py", line 5338, in show_files
    show_article(art)
  File "nodcast.py", line 3348, in show_article
    text_content = extractText(pdf_name)
  File "nodcast.py", line 323, in extractText
    with open(file, 'rb') as in_file:
FileNotFoundError: [Errno 2] No such file or directory: 'Investigating Transfer Learning in Multilingual Pre-trained Language Models through Chinese Natural Language Inference.pdf'
CRITICAL:root:
Date:2021-06-28 23:15:22.197790
Traceback (most recent call last):
  File "nodcast.py", line 6080, in <module>
    main()
  File "nodcast.py", line 6072, in main
    wrapper(start)
  File "/home/ahmad/miniconda3/lib/python3.8/curses/__init__.py", line 105, in wrapper
    return func(stdscr, *args, **kwds)
  File "nodcast.py", line 5056, in start
    show_files(save_folder, exts=['*.txt', '*.artid', "*.listid", '*.art','*.pdf','*.list','*.json','*.squad','*.prc'], extract=True)
  File "nodcast.py", line 5169, in show_files
    show_files(sfolder, exts, depth + 1)
  File "nodcast.py", line 5371, in show_files
    show_article(art)
  File "nodcast.py", line 3366, in show_article
    show_article(ext_art)
  File "nodcast.py", line 1916, in show_article
    first_frag = art["sections"][0]['fragments'][0]
IndexError: list index out of range
CRITICAL:root:
Date:2021-06-29 00:14:53.916708
Traceback (most recent call last):
  File "/home/ahmad/miniconda3/lib/python3.8/site-packages/urllib3/connection.py", line 159, in _new_conn
    conn = connection.create_connection(
  File "/home/ahmad/miniconda3/lib/python3.8/site-packages/urllib3/util/connection.py", line 84, in create_connection
    raise err
  File "/home/ahmad/miniconda3/lib/python3.8/site-packages/urllib3/util/connection.py", line 74, in create_connection
    sock.connect(sa)
OSError: [Errno 101] Network is unreachable

During handling of the above exception, another exception occurred:

Traceback (most recent call last):
  File "/home/ahmad/miniconda3/lib/python3.8/site-packages/urllib3/connectionpool.py", line 670, in urlopen
    httplib_response = self._make_request(
  File "/home/ahmad/miniconda3/lib/python3.8/site-packages/urllib3/connectionpool.py", line 381, in _make_request
    self._validate_conn(conn)
  File "/home/ahmad/miniconda3/lib/python3.8/site-packages/urllib3/connectionpool.py", line 978, in _validate_conn
    conn.connect()
  File "/home/ahmad/miniconda3/lib/python3.8/site-packages/urllib3/connection.py", line 309, in connect
    conn = self._new_conn()
  File "/home/ahmad/miniconda3/lib/python3.8/site-packages/urllib3/connection.py", line 171, in _new_conn
    raise NewConnectionError(
urllib3.exceptions.NewConnectionError: <urllib3.connection.HTTPSConnection object at 0x7f3506eb3490>: Failed to establish a new connection: [Errno 101] Network is unreachable

During handling of the above exception, another exception occurred:

Traceback (most recent call last):
  File "/home/ahmad/miniconda3/lib/python3.8/site-packages/requests/adapters.py", line 439, in send
    resp = conn.urlopen(
  File "/home/ahmad/miniconda3/lib/python3.8/site-packages/urllib3/connectionpool.py", line 726, in urlopen
    retries = retries.increment(
  File "/home/ahmad/miniconda3/lib/python3.8/site-packages/urllib3/util/retry.py", line 439, in increment
    raise MaxRetryError(_pool, url, error or ResponseError(cause))
urllib3.exceptions.MaxRetryError: HTTPSConnectionPool(host='translate.google.com', port=443): Max retries exceeded with url: /_/TranslateWebserverUi/data/batchexecute (Caused by NewConnectionError('<urllib3.connection.HTTPSConnection object at 0x7f3506eb3490>: Failed to establish a new connection: [Errno 101] Network is unreachable'))

During handling of the above exception, another exception occurred:

Traceback (most recent call last):
  File "/home/ahmad/miniconda3/lib/python3.8/site-packages/gtts/tts.py", line 263, in write_to_fp
    r = s.send(request=pr,
  File "/home/ahmad/miniconda3/lib/python3.8/site-packages/requests/sessions.py", line 643, in send
    r = adapter.send(request, **kwargs)
  File "/home/ahmad/miniconda3/lib/python3.8/site-packages/requests/adapters.py", line 516, in send
    raise ConnectionError(e, request=request)
requests.exceptions.ConnectionError: HTTPSConnectionPool(host='translate.google.com', port=443): Max retries exceeded with url: /_/TranslateWebserverUi/data/batchexecute (Caused by NewConnectionError('<urllib3.connection.HTTPSConnection object at 0x7f3506eb3490>: Failed to establish a new connection: [Errno 101] Network is unreachable'))

During handling of the above exception, another exception occurred:

Traceback (most recent call last):
  File "nodcast.py", line 6084, in <module>
    main()
  File "nodcast.py", line 6076, in main
    wrapper(start)
  File "/home/ahmad/miniconda3/lib/python3.8/curses/__init__.py", line 105, in wrapper
    return func(stdscr, *args, **kwds)
  File "nodcast.py", line 5049, in start
    list_artids(last_visited, "Recent Articles", group="last_visited")
  File "nodcast.py", line 946, in list_artids
    arts = list_articles(articles, fid, group=group)
  File "nodcast.py", line 1100, in list_articles
    show_article(articles[k])
  File "nodcast.py", line 2692, in show_article
    play(sfile, sents, art, bmark, record_all=ch == ord('S'))
  File "nodcast.py", line 1787, in play
    record(sent["text"], sfile)
  File "nodcast.py", line 1748, in record
    tts.save(sound_file)
  File "/home/ahmad/miniconda3/lib/python3.8/site-packages/gtts/tts.py", line 312, in save
    self.write_to_fp(f)
  File "/home/ahmad/miniconda3/lib/python3.8/site-packages/gtts/tts.py", line 279, in write_to_fp
    raise gTTSError(tts=self)
gtts.tts.gTTSError: Failed to connect. Probable cause: Unknown
CRITICAL:root:
Date:2021-06-29 00:44:05.812524
Traceback (most recent call last):
  File "nodcast.py", line 6093, in <module>
    main()
  File "nodcast.py", line 6085, in main
    wrapper(start)
  File "/home/ahmad/miniconda3/lib/python3.8/curses/__init__.py", line 105, in wrapper
    return func(stdscr, *args, **kwds)
  File "nodcast.py", line 5058, in start
    list_artids(last_visited, "Recent Articles", group="last_visited")
  File "nodcast.py", line 946, in list_artids
    arts = list_articles(articles, fid, group=group)
  File "nodcast.py", line 1100, in list_articles
    show_article(articles[k])
  File "nodcast.py", line 2687, in show_article
    cc += 1
UnboundLocalError: local variable 'cc' referenced before assignment
CRITICAL:root:
Date:2021-06-29 00:46:02.268913
Traceback (most recent call last):
  File "nodcast.py", line 6095, in <module>
    main()
  File "nodcast.py", line 6087, in main
    wrapper(start)
  File "/home/ahmad/miniconda3/lib/python3.8/curses/__init__.py", line 105, in wrapper
    return func(stdscr, *args, **kwds)
  File "nodcast.py", line 5060, in start
    list_artids(last_visited, "Recent Articles", group="last_visited")
  File "nodcast.py", line 946, in list_artids
    arts = list_articles(articles, fid, group=group)
  File "nodcast.py", line 1100, in list_articles
    show_article(articles[k])
  File "nodcast.py", line 2693, in show_article
    limit = 10 if not record_all else len(sents) - si
NameError: name 'record_all' is not defined
CRITICAL:root:
Date:2021-06-29 09:36:07.938354
Traceback (most recent call last):
  File "nodcast.py", line 6095, in <module>
    main()
  File "nodcast.py", line 6087, in main
    wrapper(start)
  File "/home/ahmad/miniconda3/lib/python3.8/curses/__init__.py", line 105, in wrapper
    return func(stdscr, *args, **kwds)
  File "nodcast.py", line 5060, in start
    list_artids(last_visited, "Recent Articles", group="last_visited")
  File "nodcast.py", line 946, in list_artids
    arts = list_articles(articles, fid, group=group)
  File "nodcast.py", line 1278, in list_articles
    write_article(art, folder)
  File "nodcast.py", line 1336, in write_article
    top = replace_template(template_menu["top"], "{url}", article["pdfUrl"])
KeyError: 'pdfUrl'
CRITICAL:root:
Date:2021-06-29 11:48:20.604391
Traceback (most recent call last):
  File "nodcast.py", line 6096, in <module>
    main()
  File "nodcast.py", line 6088, in main
    wrapper(start)
  File "/home/ahmad/miniconda3/lib/python3.8/curses/__init__.py", line 105, in wrapper
    return func(stdscr, *args, **kwds)
  File "nodcast.py", line 5072, in start
    show_files(save_folder, exts=['*.txt', '*.artid', "*.listid", '*.art','*.pdf','*.list','*.json','*.squad','*.prc'], extract=True)
  File "nodcast.py", line 5357, in show_files
    show_article(art)
  File "nodcast.py", line 2577, in show_article
    ch = DOWN if not player.is_playing() else ord('b')
AttributeError: 'NoneType' object has no attribute 'is_playing'
CRITICAL:root:
Date:2021-06-29 11:52:05.760587
Traceback (most recent call last):
  File "/home/ahmad/miniconda3/lib/python3.8/site-packages/urllib3/connection.py", line 159, in _new_conn
    conn = connection.create_connection(
  File "/home/ahmad/miniconda3/lib/python3.8/site-packages/urllib3/util/connection.py", line 84, in create_connection
    raise err
  File "/home/ahmad/miniconda3/lib/python3.8/site-packages/urllib3/util/connection.py", line 74, in create_connection
    sock.connect(sa)
OSError: [Errno 101] Network is unreachable

During handling of the above exception, another exception occurred:

Traceback (most recent call last):
  File "/home/ahmad/miniconda3/lib/python3.8/site-packages/urllib3/connectionpool.py", line 670, in urlopen
    httplib_response = self._make_request(
  File "/home/ahmad/miniconda3/lib/python3.8/site-packages/urllib3/connectionpool.py", line 381, in _make_request
    self._validate_conn(conn)
  File "/home/ahmad/miniconda3/lib/python3.8/site-packages/urllib3/connectionpool.py", line 978, in _validate_conn
    conn.connect()
  File "/home/ahmad/miniconda3/lib/python3.8/site-packages/urllib3/connection.py", line 309, in connect
    conn = self._new_conn()
  File "/home/ahmad/miniconda3/lib/python3.8/site-packages/urllib3/connection.py", line 171, in _new_conn
    raise NewConnectionError(
urllib3.exceptions.NewConnectionError: <urllib3.connection.HTTPSConnection object at 0x7fb693680850>: Failed to establish a new connection: [Errno 101] Network is unreachable

During handling of the above exception, another exception occurred:

Traceback (most recent call last):
  File "/home/ahmad/miniconda3/lib/python3.8/site-packages/requests/adapters.py", line 439, in send
    resp = conn.urlopen(
  File "/home/ahmad/miniconda3/lib/python3.8/site-packages/urllib3/connectionpool.py", line 726, in urlopen
    retries = retries.increment(
  File "/home/ahmad/miniconda3/lib/python3.8/site-packages/urllib3/util/retry.py", line 439, in increment
    raise MaxRetryError(_pool, url, error or ResponseError(cause))
urllib3.exceptions.MaxRetryError: HTTPSConnectionPool(host='translate.google.com', port=443): Max retries exceeded with url: /_/TranslateWebserverUi/data/batchexecute (Caused by NewConnectionError('<urllib3.connection.HTTPSConnection object at 0x7fb693680850>: Failed to establish a new connection: [Errno 101] Network is unreachable'))

During handling of the above exception, another exception occurred:

Traceback (most recent call last):
  File "/home/ahmad/miniconda3/lib/python3.8/site-packages/gtts/tts.py", line 263, in write_to_fp
    r = s.send(request=pr,
  File "/home/ahmad/miniconda3/lib/python3.8/site-packages/requests/sessions.py", line 643, in send
    r = adapter.send(request, **kwargs)
  File "/home/ahmad/miniconda3/lib/python3.8/site-packages/requests/adapters.py", line 516, in send
    raise ConnectionError(e, request=request)
requests.exceptions.ConnectionError: HTTPSConnectionPool(host='translate.google.com', port=443): Max retries exceeded with url: /_/TranslateWebserverUi/data/batchexecute (Caused by NewConnectionError('<urllib3.connection.HTTPSConnection object at 0x7fb693680850>: Failed to establish a new connection: [Errno 101] Network is unreachable'))

During handling of the above exception, another exception occurred:

Traceback (most recent call last):
  File "nodcast.py", line 6096, in <module>
    main()
  File "nodcast.py", line 6088, in main
    wrapper(start)
  File "/home/ahmad/miniconda3/lib/python3.8/curses/__init__.py", line 105, in wrapper
    return func(stdscr, *args, **kwds)
  File "nodcast.py", line 5072, in start
    show_files(save_folder, exts=['*.txt', '*.artid', "*.listid", '*.art','*.pdf','*.list','*.json','*.squad','*.prc'], extract=True)
  File "nodcast.py", line 5185, in show_files
    show_files(sfolder, exts, depth + 1)
  File "nodcast.py", line 5387, in show_files
    show_article(art)
  File "nodcast.py", line 2701, in show_article
    play(sfile, sents, art, bmark, record_all=False)
  File "nodcast.py", line 1790, in play
    record(sent["text"], sfile)
  File "nodcast.py", line 1751, in record
    tts.save(sound_file)
  File "/home/ahmad/miniconda3/lib/python3.8/site-packages/gtts/tts.py", line 312, in save
    self.write_to_fp(f)
  File "/home/ahmad/miniconda3/lib/python3.8/site-packages/gtts/tts.py", line 279, in write_to_fp
    raise gTTSError(tts=self)
gtts.tts.gTTSError: Failed to connect. Probable cause: Unknown
CRITICAL:root:
Date:2021-06-29 12:50:49.595093
Traceback (most recent call last):
  File "/home/ahmad/miniconda3/lib/python3.8/shutil.py", line 788, in move
    os.rename(src, real_dst)
FileNotFoundError: [Errno 2] No such file or directory: '/home/ahmad/Documents/Checkideh/Common Sense RC/Files/2021-06-26/Investigating Transfer Learning in Multilingual Pre-trained Language Models through Chinese Natural Language Inference.artid' -> '/home/ahmad/Documents/Checkideh/Common Sense RC/Files/2021-06-26/Investigating Transfer Learning in Multilingual Pre-trained Language Models through Chinese Natural Language Inference.artid'

During handling of the above exception, another exception occurred:

Traceback (most recent call last):
  File "nodcast.py", line 6098, in <module>
    main()
  File "nodcast.py", line 6090, in main
    wrapper(start)
  File "/home/ahmad/miniconda3/lib/python3.8/curses/__init__.py", line 105, in wrapper
    return func(stdscr, *args, **kwds)
  File "nodcast.py", line 5073, in start
    show_files(save_folder, exts=['*.txt', '*.artid', "*.listid", '*.art','*.pdf','*.list','*.json','*.squad','*.prc'], extract=True)
  File "nodcast.py", line 5186, in show_files
    show_files(sfolder, exts, depth + 1)
  File "nodcast.py", line 5389, in show_files
    show_article(art)
  File "nodcast.py", line 3343, in show_article
    shutil.move(f_ref, _new_name)
  File "/home/ahmad/miniconda3/lib/python3.8/shutil.py", line 802, in move
    copy_function(src, real_dst)
  File "/home/ahmad/miniconda3/lib/python3.8/shutil.py", line 432, in copy2
    copyfile(src, dst, follow_symlinks=follow_symlinks)
  File "/home/ahmad/miniconda3/lib/python3.8/shutil.py", line 261, in copyfile
    with open(src, 'rb') as fsrc, open(dst, 'wb') as fdst:
FileNotFoundError: [Errno 2] No such file or directory: '/home/ahmad/Documents/Checkideh/Common Sense RC/Files/2021-06-26/Investigating Transfer Learning in Multilingual Pre-trained Language Models through Chinese Natural Language Inference.artid'
